Workbook

Sheet Cover
A1: NORTHWALL RESEARCH
A2: Alamos Gold Inc. (AGI)
A3: Gold producers · Analyst: Basel Al-Ghousein · Model version v2026Q2 · Built 2026-10-27
A5: Rating | B5: =Valuation!$B$39 -> Buy
A6: Price target (USD) | B6: =Valuation!$B$34 -> 39
A7: Share price (USD), NYSE close Oct 26, 2026 (Stock Analysis) | B7: =Valuation!$B$5 -> 30.21
A8: Implied all-in return | B8: =Valuation!$B$38 -> 0.29625952
A9: Valuation method 1 | B9: =Valuation!$B$25 -> 42.353085
A10: Valuation method 2 | B10: =Valuation!$B$28 -> 34.973722
A11: DCF cross-check per share | B11: =Valuation!$B$55 -> 42.925189
A12: Cost of equity (CAPM) | B12: =Valuation!$B$16 -> 0.0997
A13: Market-implied growth | B13: =Valuation!$B$61 -> -0.016068692
A14: All integrity checks pass | B14: =IF(Checks!$D$12,"Yes","NO - see Checks") -> Yes
A16: Colour code
A17: Blue: typed input with a source (Inputs sheet only)
A18: Black: formula
A19: Green: link to another sheet
A20: Yellow fill: key assumption or output
A22: Sheets
A23: Inputs | B23: Every typed number, with its source
A24: Model | B24: Operations and financials, H1 actual + H2 estimate
A25: Valuation | B25: Target methods, CAPM/WACC, DCF, reverse DCF, residual income, justified P/E
A26: NAV | B26: Asset-life cash flows (resource names)
A27: Sensitivity | B27: Target and DCF grids
A28: Ratios | B28: DuPont, cash conversion, leverage, payout
A29: Comps | B29: Peer table
A30: Checks | B30: Integrity checks; all must be TRUE
A31: Log | B31: Every change, dated, with its reason

Sheet Inputs
A1: Alamos Gold Inc. (AGI) — Inputs
A2: Every typed number in the model lives here, in blue, with its source. Change inputs here only.
A4: House price deck (from data/price_deck.yaml)
A5: Input | B5: Unit | C5: 2025A | D5: H1-26A | E5: H2-26E | F5: 2026E | G5: 2027E | H5: 2028E | I5: 2029E | J5: 2030E | K5: Source
A6: Gold price, house deck | B6: US$/oz | E6: 4200 | G6: 4000 | H6: 3800 | I6: 3600 | J6: 3500 | K6: Northwall deck: Q3-26 ~4,350 and Q4-26 4,050 (avg 4,200); spot ~US$4,000 on Oct 23, 2026 (pricegold.net); steps to a 3,500 long-term real price
A8: Company drivers by period
A9: Input | B9: Unit | C9: 2025A | D9: H1-26A | E9: H2-26E | F9: 2026E | G9: 2027E | H9: 2028E | I9: 2029E | J9: 2030E | K9: Source
A10: Gold production | B10: koz | C10: 545.4 | D10: 254.5 | E10: 280.5 | G10: 640 | H10: 770 | I10: 870 | J10: 960 | K10: 2025A: Q4-25 release. H1-26A: Q2-26 release. H2-26E: Northwall, inside revised 510-560k guidance. 2027E+: Northwall, below original 3-yr guidance (650-730k, 755-835k) and the ~1 Moz by 2030 target
A11: Realized gold price, reported | B11: US$/oz | C11: 3372 | D11: 4660 | K11: Q4-25 release; Q2-26 release
A12: Revenue, reported | B12: US$M | C12: 1808.8 | D12: 1190.8 | K12: Q4-25 release; Q2-26 release
A13: AISC | B13: US$/oz | C13: 1524 | D13: 1793 | E13: 1855 | G13: 1550 | H13: 1350 | I13: 1250 | J13: 1200 | K13: Reported 2025 and H1-26; H2-26E implied by the US$1,825 guidance midpoint; Northwall thereafter (IGD expansion AISC US$1,025, Lynn Lake US$829 per company)
A14: Adjusted EPS, reported | B14: US$ | C14: 1.4 | D14: 1.14 | K14: Q4-25 release; Q2-26 release
A15: Operating cash flow, reported | B15: US$M | C15: 795.3 | D15: 474.3 | K15: Q4-25 release; Q2-26 release
A16: Free cash flow, reported | B16: US$M | C16: 351.7 | D16: 245.2 | K16: Q4-25 release; Q2-26 release
A17: Growth capital | B17: US$M | E17: 345 | G17: 600 | H17: 420 | I17: 150 | J17: 0 | K17: Northwall: 2026 guidance US$657-720M less H1; Lynn Lake US$871M remaining, IGD mill, PDA
A18: Capitalized exploration | B18: US$M | E18: 30 | G18: 60 | H18: 60 | I18: 60 | J18: 60 | K18: 2026 guidance US$60M
A19: Basic shares | B19: M | C19: 420 | D19: 419.8 | E19: 418.6 | F19: 418.6 | G19: 418.6 | H19: 418.6 | I19: 418.6 | J19: 418.6 | K19: Weighted basic shares per filings; Mar 31 count 419.96M less 1.40M bought back in Q2
A20: Dividend per share | B20: US$ | C20: 0.1 | D20: 0.08 | E20: 0.08 | G20: 0.16 | H20: 0.16 | I20: 0.16 | J20: 0.16 | K20: US$0.04 quarterly after the Q1-26 increase
A21: Share buybacks | B21: US$M | E21: 50 | G21: 0 | H21: 0 | I21: 0 | J21: 0 | K21: Northwall: Q2-26 pace for H2; none assumed thereafter
A22: Net debt, reported (negative = net cash) | B22: US$M | D22: -436.9 | K22: Cash US$636.9M (Jun 30, 2026) less US$200M drawn (Mar 31, 2026 statements)
A23: Shareholders' equity, reported | B23: US$M | D23: 4607.8 | K23: Mar 31, 2026 interim statements (proxy for Jun 30)
A25: Scalar inputs: market data, operating assumptions, valuation parameters
A26: Input | B26: Unit | C26: Value | K26: Source
A27: Share price | C27: 30.21 | K27: NYSE close Oct 26, 2026 (Stock Analysis)
A28: Model currency per listing currency | C28: 1 | K28: Same currency
A29: Basic shares outstanding | B29: M | C29: 418.6 | K29: Latest company filing
A30: Net debt at last balance sheet (negative = net cash) | B30: M | C30: -436.9 | K30: Latest quarterly filing
A31: Equity beta | C31: 1 | K31: Northwall assumption pending sourcing
A32: Pre-tax cost of debt | C32: 0.06 | K32: Northwall assumption: credit facility pricing
A33: Marginal tax rate | C33: 0.25 | K33: Statutory combined rate
A34: Gross debt | B34: M | C34: 200 | K34: Latest quarterly filing
A35: Weight on valuation method 1 | C35: 0.5 | K35: Northwall method: equal weight
A36: Target multiple, method 1 | C36: 1 | K36: Northwall: in line with intermediate producers at a long-term deck below spot
A37: Target multiple, method 2 | C37: 10 | K37: Northwall: below Alamos trailing 13.7x, above Kinross 5.8x
A38: Next-12-month dividend per share | C38: 0.16 | K38: US$0.04 quarterly (Q2-26 release)
A39: Target rounding increment | C39: 1 | K39: House style
A40: Buy threshold: expected 12-month total return | C40: 0.15 | K40: Northwall rating definitions
A41: Terminal growth for DCF cross-check (nominal) | C41: 0.02 | K41: Northwall: 0% for depleting oil assets, 2% for long-life gold portfolios
A42: Investments not captured in FCFF | B42: M | C42: 0 | K42: Balance sheet
A43: Effective income and mining tax rate | C43: 0.25 | K43: Northwall: Canadian and Mexican income and mining taxes
...

Sheet Model
A1: Alamos Gold Inc. — Operating and financial model (USD millions unless noted)
A2: H1-26A = reported six months; H2-26E = Northwall estimate; 2026E = H1 + H2. All cells are formulas.
A4: Line | B4: Unit | C4: 2025A | D4: H1-26A | E4: H2-26E | F4: 2026E | G4: 2027E | H4: 2028E | I4: 2029E | J4: 2030E | K4: Method
A5: Production and costs
A6: Gold production | B6: koz | C6: =Inputs!C10 -> 545.4 | D6: =Inputs!D10 -> 254.5 | E6: =Inputs!E10 -> 280.5 | F6: =D6+E6 -> 535 | G6: =Inputs!G10 -> 640 | H6: =Inputs!H10 -> 770 | I6: =Inputs!I10 -> 870 | J6: =Inputs!J10 -> 960
A7: Realized gold price | B7: US$/oz | C7: =Inputs!C11 -> 3372 | D7: =Inputs!D11 -> 4660 | E7: =Inputs!E6 -> 4200 | F7: =(D7*D6+E7*E6)/F6 -> 4418.8224 | G7: =Inputs!G6 -> 4000 | H7: =Inputs!H6 -> 3800 | I7: =Inputs!I6 -> 3600 | J7: =Inputs!J6 -> 3500 | K7: Actuals as reported; forecasts at the house deck
A8: All-in sustaining cost | B8: US$/oz | C8: =Inputs!C13 -> 1524 | D8: =Inputs!D13 -> 1793 | E8: =Inputs!E13 -> 1855 | F8: =(D8*D6+E8*E6)/F6 -> 1825.5065 | G8: =Inputs!G13 -> 1550 | H8: =Inputs!H13 -> 1350 | I8: =Inputs!I13 -> 1250 | J8: =Inputs!J13 -> 1200
A9: AISC margin | B9: US$/oz | C9: =C7-C8 -> 1848 | D9: =D7-D8 -> 2867 | E9: =E7-E8 -> 2345 | F9: =F7-F8 -> 2593.3159 | G9: =G7-G8 -> 2450 | H9: =H7-H8 -> 2450 | I9: =I7-I8 -> 2350 | J9: =J7-J8 -> 2300
A10: Income statement
A11: Revenue | B11: US$M | C11: =Inputs!C12 -> 1808.8 | D11: =Inputs!D12 -> 1190.8 | E11: =E6*E7/1000 -> 1178.1 | F11: =D11+E11 -> 2368.9 | G11: =G6*G7/1000 -> 2560 | H11: =H6*H7/1000 -> 2926 | I11: =I6*I7/1000 -> 3132 | J11: =J6*J7/1000 -> 3360
A12: AISC margin | B12: US$M | C12: =C9*C6/1000 -> 1007.8992 | D12: =D9*D6/1000 -> 729.6515 | E12: =E9*E6/1000 -> 657.7725 | F12: =D12+E12 -> 1387.424 | G12: =G9*G6/1000 -> 1568 | H12: =H9*H6/1000 -> 1886.5 | I12: =I9*I6/1000 -> 2044.5 | J12: =J9*J6/1000 -> 2208
A13: Income and mining taxes | B13: US$M | E13: =E12*Inputs!$C$43 -> 164.44313 | G13: =G12*Inputs!$C$43 -> 392 | H13: =H12*Inputs!$C$43 -> 471.625 | I13: =I12*Inputs!$C$43 -> 511.125 | J13: =J12*Inputs!$C$43 -> 552 | K13: Effective rate on AISC margin
A14: Basic shares | B14: M | C14: =Inputs!C19 -> 420 | D14: =Inputs!D19 -> 419.8 | E14: =Inputs!E19 -> 418.6 | F14: =Inputs!F19 -> 418.6 | G14: =Inputs!G19 -> 418.6 | H14: =Inputs!H19 -> 418.6 | I14: =Inputs!I19 -> 418.6 | J14: =Inputs!J19 -> 418.6
A15: Adjusted EPS | B15: US$ | C15: =Inputs!C14 -> 1.4 | D15: =Inputs!D14 -> 1.14 | E15: =(E7-E8-Inputs!$C$45)*E6/1000*(1-Inputs!$C$43)/E14 -> 1.0780085 | F15: =D15+E15 -> 2.2180085 | G15: =(G7-G8-Inputs!$C$45)*G6/1000*(1-Inputs!$C$43)/G14 -> 2.5800287 | H15: =(H7-H8-Inputs!$C$45)*H6/1000*(1-Inputs!$C$43)/H14 -> 3.104097 | I15: =(I7-I8-Inputs!$C$45)*I6/1000*(1-Inputs!$C$43)/I14 -> 3.3513497 | J15: =(J7-J8-Inputs!$C$45)*J6/1000*(1-Inputs!$C$43)/J14 -> 3.6120401 | K15: Depreciation in excess of sustaining capital deducted
A16: Adjusted net income | B16: US$M | C16: =C15*C14 -> 588 | D16: =D15*D14 -> 478.572 | E16: =E15*E14 -> 451.25437 | F16: =D16+E16 -> 929.82637 | G16: =G15*G14 -> 1080 | H16: =H15*H14 -> 1299.375 | I16: =I15*I14 -> 1402.875 | J16: =J15*J14 -> 1512
A17: Cash flow
A18: Operating cash flow | B18: US$M | C18: =Inputs!C15 -> 795.3 | D18: =Inputs!D15 -> 474.3 | E18: =(E7-E8+Inputs!$C$44)*E6/1000-E13 -> 619.55438 | F18: =D18+E18 -> 1093.8544 | G18: =(G7-G8+Inputs!$C$44)*G6/1000-G13 -> 1464 | H18: =(H7-H8+Inputs!$C$44)*H6/1000-H13 -> 1761.375 | I18: =(I7-I8+Inputs!$C$44)*I6/1000-I13 -> 1924.875 | J18: =(J7-J8+Inputs!$C$44)*J6/1000-J13 -> 2088
A19: Cash flow per share | B19: US$ | C19: =C18/C14 -> 1.8935714 | D19: =D18/D14 -> 1.1298237 | E19: =E18/E14 -> 1.480063 | F19: =F18/F14 -> 2.6131256 | G19: =G18/G14 -> 3.4973722 | H19: =H18/H14 -> 4.2077759 | I19: =I18/I14 -> 4.5983636 | J19: =J18/J14 -> 4.9880554
A20: Sustaining capital | B20: US$M | E20: =Inputs!$C$44*E6/1000 -> 126.225 | G20: =Inputs!$C$44*G6/1000 -> 288 | H20: =Inputs!$C$44*H6/1000 -> 346.5 | I20: =Inputs!$C$44*I6/1000 -> 391.5 | J20: =Inputs!$C$44*J6/1000 -> 432
A21: Growth capital | B21: US$M | E21: =Inputs!E17 -> 345 | G21: =Inputs!G17 -> 600 | H21: =Inputs!H17 -> 420 | I21: =Inputs!I17 -> 150 | J21: =Inputs!J17 -> 0
A22: Capitalized exploration | B22: US$M | E22: =Inputs!E18 -> 30 | G22: =Inputs!G18 -> 60 | H22: =Inputs!H18 -> 60 | I22: =Inputs!I18 -> 60 | J22: =Inputs!J18 -> 60
A23: Free cash flow | B23: US$M | C23: =Inputs!C16 -> 351.7 | D23: =Inputs!D16 -> 245.2 | E23: =E18-E20-E21-E22 -> 118.32937 | F23: =D23+E23 -> 363.52938 | G23: =G18-G20-G21-G22 -> 516 | H23: =H18-H20-H21-H22 -> 934.875 | I23: =I18-I20-I21-I22 -> 1323.375 | J23: =J18-J20-J21-J22 -> 1596
A24: Free cash flow to the firm | B24: US$M | G24: =G23 -> 516 | H24: =H23 -> 934.875 | I24: =I23 -> 1323.375 | J24: =J23 -> 1596 | K24: After-tax interest on US$200M is immaterial
A25: Dividend per share | B25: US$ | C25: =Inputs!C20 -> 0.1 | D25: =Inputs!D20 -> 0.08 | E25: =Inputs!E20 -> 0.08 | F25: =D25+E25 -> 0.16 | G25: =Inputs!G20 -> 0.16 | H25: =Inputs!H20 -> 0.16 | I25: =Inputs!I20 -> 0.16 | J25: =Inputs!J20 -> 0.16
A26: Dividends paid | B26: US$M | E26: =E25*E14 -> 33.488 | G26: =G25*G14 -> 66.976 | H26: =H25*H14 -> 66.976 | I26: =I25*I14 -> 66.976 | J26: =J25*J14 -> 66.976
A27: Share buybacks | B27: US$M | E27: =Inputs!E21 -> 50 | G27: =Inputs!G21 -> 0 | H27: =Inputs!H21 -> 0 | I27: =Inputs!I21 -> 0 | J27: =Inputs!J21 -> 0
A28: Balance sheet
A29: Net debt (negative = net cash) | B29: US$M | D29: =Inputs!D22 -> -436.9 | E29: =D29-E23+E26+E27 -> -471.74138 | F29: =E29 -> -471.74138 | G29: =F29-G23+G26+G27 -> -920.76537 | H29: =G29-H23+H26+H27 -> -1788.6644 | I29: =H29-I23+I26+I27 -> -3045.0634 | J29: =I29-J23+J26+J27 -> -4574.0874
A30: Shareholders' equity, period end | B30: US$M | D30: =Inputs!D23 -> 4607.8 | E30: =D30+E16-E26-E27 -> 4975.5664 | F30: =E30 -> 4975.5664 | G30: =F30+G16-G26-G27 -> 5988.5904 | H30: =G30+H16-H26-H27 -> 7220.9894 | I30: =H30+I16-I26-I27 -> 8556.8884 | J30: =I30+J16-J26-J27 -> 10001.912 | K30: H1 uses Mar 31, 2026 reported equity as a proxy

Sheet Valuation
A1: Alamos Gold Inc. — Valuation and price target
A2: Target methods first; CFA Level II cross-checks (DCF, reverse DCF, residual income, justified P/E) follow.
A4: Market data
A5: Share price (USD) | B5: =Inputs!$C$27 -> 30.21 | C5: NYSE close Oct 26, 2026 (Stock Analysis)
A6: Share price in model currency (USD) | B6: =Inputs!$C$27*Inputs!$C$28 -> 30.21 | C6: Converted when the listing currency differs from the reporting currency
A7: Basic shares outstanding (M) | B7: =Inputs!$C$29 -> 418.6
A8: Market capitalization (M) | B8: =Valuation!$B$6*Valuation!$B$7 -> 12645.906
A9: Net debt (cash) at last balance sheet (M) | B9: =Inputs!$C$30 -> -436.9 | C9: Negative = net cash
A10: Enterprise value (M) | B10: =Valuation!$B$8+Valuation!$B$9 -> 12209.006 | C10: Market cap + net debt
A12: Required return on equity (CAPM) and WACC — CFA L2 Equity: Return Concepts; Corporate Issuers: Cost of Capital
A13: Risk-free rate (US 10-yr) | B13: =Inputs!$C$52 -> 0.0497 | C13: House deck
A14: Equity beta | B14: =Inputs!$C$31 -> 1 | C14: Northwall assumption pending sourcing
A15: Equity risk premium | B15: =Inputs!$C$53 -> 0.05 | C15: House deck
A16: Cost of equity: rf + beta x ERP | B16: =Valuation!$B$13+Valuation!$B$14*Valuation!$B$15 -> 0.0997 | C16: CAPM
A17: Pre-tax cost of debt | B17: =Inputs!$C$32 -> 0.06 | C17: Northwall assumption: credit facility pricing
A18: Marginal tax rate | B18: =Inputs!$C$33 -> 0.25
A19: Debt weight: D / (D + E), market values | B19: =Inputs!$C$34/(Inputs!$C$34+Valuation!$B$8) -> 0.015569163 | C19: Gross debt at market cap
A20: WACC | B20: =Valuation!$B$16*(1-Valuation!$B$19)+Valuation!$B$17*(1-Valuation!$B$18)*Valuation!$B$19 -> 0.098848367 | C20: ke x E/V + kd x (1 - t) x D/V
A22: Target method 1: P/NAV — method 2: P/CF
A23: NAV per share (NAV sheet) | B23: =NAV!$B$18 -> 42.353085
A24: Target P/NAV multiple | B24: =Inputs!$C$36 -> 1 | C24: Northwall: in line with intermediate producers at a long-term deck below spot
A25: Method 1 value per share | B25: =Valuation!$B$23*Valuation!$B$24 -> 42.353085
A26: Cash flow per share, 2027E | B26: =Model!$G$19 -> 3.4973722
A27: Target P/CF multiple, 2027E | B27: =Inputs!$C$37 -> 10 | C27: Northwall: below Alamos trailing 13.7x, above Kinross 5.8x
A28: Method 2 value per share | B28: =Valuation!$B$26*Valuation!$B$27 -> 34.973722
A29: Price target and rating
A30: Weight on method 1 | B30: =Inputs!$C$35 -> 0.5
A31: Weight on method 2 | B31: =1-Inputs!$C$35 -> 0.5
A32: Blended value per share (USD) | B32: =Valuation!$B$30*Valuation!$B$25+Valuation!$B$31*Valuation!$B$28 -> 38.663403
A33: Blended value per share (USD) | B33: =Valuation!$B$32/Inputs!$C$28 -> 38.663403 | C33: Converted to listing currency
A34: 12-month price target (USD), rounded | B34: =MROUND(Valuation!$B$33,Inputs!$C$39) -> 39 | C34: Rounded to the house increment
A35: Next-12-month dividend per share (listing currency) | B35: =Inputs!$C$38 -> 0.16 | C35: US$0.04 quarterly (Q2-26 release)
A36: Implied price return | B36: =Valuation!$B$34/Valuation!$B$5-1 -> 0.29096326
A37: Dividend yield | B37: =Valuation!$B$35/Valuation!$B$5 -> 0.0052962595
A38: Implied all-in return | B38: =Valuation!$B$36+Valuation!$B$37 -> 0.29625952 | C38: Rating bands: Buy > 15%, Hold 0–15%, Sell < 0%
A39: Rating | B39: =IF(Valuation!$B$38>Inputs!$C$40,"Buy",IF(Valuation!$B$38>=0,"Hold","Sell")) -> Buy
A41: Cross-check 1: two-stage FCFF DCF — CFA L2 Equity: Free Cash Flow Valuation
A42: Valuation date: Dec 31, 2026. FCFF discounted at WACC, end-year; Gordon growth terminal value on 2030E FCFF.
A43: Year | B43: 2027E | C43: 2028E | D43: 2029E | E43: 2030E
A44: FCFF (USD M) | B44: =Model!$G$24 -> 516 | C44: =Model!$H$24 -> 934.875 | D44: =Model!$I$24 -> 1323.375 | E44: =Model!$J$24 -> 1596
...

Sheet NAV
A1: Alamos Gold Inc. — Net asset value (5% real, Dec 31, 2026)
A2: Production per Model to 2030E, flat to 2036, then a 7% annual decline to 2050.
A4: Year | C4: 2027 | D4: 2028 | E4: 2029 | F4: 2030 | G4: 2031 | H4: 2032 | I4: 2033 | J4: 2034 | K4: 2035 | L4: 2036 | M4: 2037 | N4: 2038 | O4: 2039 | P4: 2040 | Q4: 2041 | R4: 2042 | S4: 2043 | T4: 2044 | U4: 2045 | V4: 2046 | W4: 2047 | X4: 2048 | Y4: 2049 | Z4: 2050
A5: Gold production | B5: koz | C5: =Model!$G$6 -> 640 | D5: =Model!$H$6 -> 770 | E5: =Model!$I$6 -> 870 | F5: =Model!$J$6 -> 960 | G5: =Inputs!$C$46 -> 960 | H5: =Inputs!$C$46 -> 960 | I5: =Inputs!$C$46 -> 960 | J5: =Inputs!$C$46 -> 960 | K5: =Inputs!$C$46 -> 960 | L5: =Inputs!$C$46 -> 960 | M5: =L5*(1-Inputs!$C$47) -> 892.8 | N5: =M5*(1-Inputs!$C$47) -> 830.304 | O5: =N5*(1-Inputs!$C$47) -> 772.18272 | P5: =O5*(1-Inputs!$C$47) -> 718.12993 | Q5: =P5*(1-Inputs!$C$47) -> 667.86083 | R5: =Q5*(1-Inputs!$C$47) -> 621.11058 | S5: =R5*(1-Inputs!$C$47) -> 577.63284 | T5: =S5*(1-Inputs!$C$47) -> 537.19854 | ... Z5: =Y5*(1-Inputs!$C$47) -> 347.56218
A6: Gold price | B6: US$/oz | C6: =Inputs!G6 -> 4000 | D6: =Inputs!H6 -> 3800 | E6: =Inputs!I6 -> 3600 | F6: =Inputs!J6 -> 3500 | G6: =Inputs!$C$51 -> 3500 | H6: =Inputs!$C$51 -> 3500 | I6: =Inputs!$C$51 -> 3500 | J6: =Inputs!$C$51 -> 3500 | K6: =Inputs!$C$51 -> 3500 | L6: =Inputs!$C$51 -> 3500 | M6: =Inputs!$C$51 -> 3500 | N6: =Inputs!$C$51 -> 3500 | ... Z6: =Inputs!$C$51 -> 3500
A7: AISC | B7: US$/oz | C7: =Model!$G$8 -> 1550 | D7: =Model!$H$8 -> 1350 | E7: =Model!$I$8 -> 1250 | F7: =Model!$J$8 -> 1200 | G7: =Inputs!$C$48 -> 1200 | H7: =Inputs!$C$48 -> 1200 | I7: =Inputs!$C$48 -> 1200 | J7: =Inputs!$C$48 -> 1200 | K7: =Inputs!$C$48 -> 1200 | L7: =Inputs!$C$48 -> 1200 | M7: =Inputs!$C$48 -> 1200 | N7: =Inputs!$C$48 -> 1200 | ... Z7: =Inputs!$C$48 -> 1200
A8: Growth capital | B8: US$M | C8: =Model!$G$21 -> 600 | D8: =Model!$H$21 -> 420 | E8: =Model!$I$21 -> 150 | F8: =Model!$J$21 -> 0 | G8: =0 -> 0 | H8: =0 -> 0 | I8: =0 -> 0 | J8: =0 -> 0 | K8: =0 -> 0 | L8: =0 -> 0 | M8: =0 -> 0 | N8: =0 -> 0 | ... Z8: =0 -> 0
A9: Exploration | B9: US$M | C9: =Model!$G$22 -> 60 | D9: =Model!$H$22 -> 60 | E9: =Model!$I$22 -> 60 | F9: =Model!$J$22 -> 60 | G9: =Inputs!$C$49 -> 30 | H9: =Inputs!$C$49 -> 30 | I9: =Inputs!$C$49 -> 30 | J9: =Inputs!$C$49 -> 30 | K9: =Inputs!$C$49 -> 30 | L9: =Inputs!$C$49 -> 30 | M9: =Inputs!$C$49 -> 30 | N9: =Inputs!$C$49 -> 30 | ... Z9: =Inputs!$C$49 -> 30
A10: After-tax free cash flow | B10: US$M | C10: =(C6-C7)*C5/1000*(1-Inputs!$C$43)-C8-C9 -> 516 | D10: =(D6-D7)*D5/1000*(1-Inputs!$C$43)-D8-D9 -> 934.875 | E10: =(E6-E7)*E5/1000*(1-Inputs!$C$43)-E8-E9 -> 1323.375 | F10: =(F6-F7)*F5/1000*(1-Inputs!$C$43)-F8-F9 -> 1596 | G10: =(G6-G7)*G5/1000*(1-Inputs!$C$43)-G8-G9 -> 1626 | H10: =(H6-H7)*H5/1000*(1-Inputs!$C$43)-H8-H9 -> 1626 | I10: =(I6-I7)*I5/1000*(1-Inputs!$C$43)-I8-I9 -> 1626 | J10: =(J6-J7)*J5/1000*(1-Inputs!$C$43)-J8-J9 -> 1626 | ... Z10: =(Z6-Z7)*Z5/1000*(1-Inputs!$C$43)-Z8-Z9 -> 569.54476
A11: Discount factor (mid-year) | C11: =1/(1+Inputs!$C$50)^(2027-2026-0.5) -> 0.97590007 | D11: =1/(1+Inputs!$C$50)^(2028-2026-0.5) -> 0.92942864 | E11: =1/(1+Inputs!$C$50)^(2029-2026-0.5) -> 0.88517013 | F11: =1/(1+Inputs!$C$50)^(2030-2026-0.5) -> 0.84301918 | G11: =1/(1+Inputs!$C$50)^(2031-2026-0.5) -> 0.80287541 | H11: =1/(1+Inputs!$C$50)^(2032-2026-0.5) -> 0.76464324 | I11: =1/(1+Inputs!$C$50)^(2033-2026-0.5) -> 0.72823166 | J11: =1/(1+Inputs!$C$50)^(2034-2026-0.5) -> 0.69355396 | K11: =1/(1+Inputs!$C$50)^(2035-2026-0.5) -> 0.66052758 | L11: =1/(1+Inputs!$C$50)^(2036-2026-0.5) -> 0.62907389 | M11: =1/(1+Inputs!$C$50)^(2037-2026-0.5) -> 0.59911799 | N11: =1/(1+Inputs!$C$50)^(2038-2026-0.5) -> 0.57058856 | O11: =1/(1+Inputs!$C$50)^(2039-2026-0.5) -> 0.54341768 | P11: =1/(1+Inputs!$C$50)^(2040-2026-0.5) -> 0.51754064 | Q11: =1/(1+Inputs!$C$50)^(2041-2026-0.5) -> 0.49289585 | R11: =1/(1+Inputs!$C$50)^(2042-2026-0.5) -> 0.46942462 | S11: =1/(1+Inputs!$C$50)^(2043-2026-0.5) -> 0.44707107 | T11: =1/(1+Inputs!$C$50)^(2044-2026-0.5) -> 0.42578197 | U11: =1/(1+Inputs!$C$50)^(2045-2026-0.5) -> 0.40550664 | V11: =1/(1+Inputs!$C$50)^(2046-2026-0.5) -> 0.3861968 | W11: =1/(1+Inputs!$C$50)^(2047-2026-0.5) -> 0.36780647 | X11: =1/(1+Inputs!$C$50)^(2048-2026-0.5) -> 0.35029188 | Y11: =1/(1+Inputs!$C$50)^(2049-2026-0.5) -> 0.33361131 | Z11: =1/(1+Inputs!$C$50)^(2050-2026-0.5) -> 0.31772506
A12: Present value | B12: US$M | C12: =C10*C11 -> 503.56444 | D12: =D10*D11 -> 868.8996 | E12: =E10*E11 -> 1171.412 | F12: =F10*F11 -> 1345.4586 | G12: =G10*G11 -> 1305.4754 | H12: =H10*H11 -> 1243.3099 | I12: =I10*I11 -> 1184.1047 | J12: =J10*J11 -> 1127.7187 | ... Z12: =Z10*Z11 -> 180.95864
A14: NAV summary
A15: Operating mines and projects | B15: =SUM(C12:Z12) -> 17257.26
A16: Net cash, Dec 31, 2026E | B16: =-Model!$F$29 -> 471.74138
A17: Net asset value | B17: =NAV!$B$15+NAV!$B$16 -> 17729.001
A18: NAV per share (US$) | B18: =NAV!$B$17/Inputs!$C$29 -> 42.353085

Sheet Sensitivity
A1: Alamos Gold Inc. — Sensitivity
A2: Every cell is a live formula on the model; nothing is pasted.
A4: Price target (USD, before rounding) vs. the two valuation multiples
A5: P/NAV down, P/CF 2027E across | B5: 8 | C5: 9 | D5: 10 | E5: 11 | F5: 12
A6: 0.8 | B6: =(Inputs!$C$35*$A6*Valuation!$B$23+(1-Inputs!$C$35)*B$5*Valuation!$B$26)/Inputs!$C$28 -> 30.930723 | C6: =(Inputs!$C$35*$A6*Valuation!$B$23+(1-Inputs!$C$35)*C$5*Valuation!$B$26)/Inputs!$C$28 -> 32.679409 | D6: =(Inputs!$C$35*$A6*Valuation!$B$23+(1-Inputs!$C$35)*D$5*Valuation!$B$26)/Inputs!$C$28 -> 34.428095 | E6: =(Inputs!$C$35*$A6*Valuation!$B$23+(1-Inputs!$C$35)*E$5*Valuation!$B$26)/Inputs!$C$28 -> 36.176781 | F6: =(Inputs!$C$35*$A6*Valuation!$B$23+(1-Inputs!$C$35)*F$5*Valuation!$B$26)/Inputs!$C$28 -> 37.925467
A7: 0.9 | B7: =(Inputs!$C$35*$A7*Valuation!$B$23+(1-Inputs!$C$35)*B$5*Valuation!$B$26)/Inputs!$C$28 -> 33.048377 | C7: =(Inputs!$C$35*$A7*Valuation!$B$23+(1-Inputs!$C$35)*C$5*Valuation!$B$26)/Inputs!$C$28 -> 34.797063 | D7: =(Inputs!$C$35*$A7*Valuation!$B$23+(1-Inputs!$C$35)*D$5*Valuation!$B$26)/Inputs!$C$28 -> 36.545749 | E7: =(Inputs!$C$35*$A7*Valuation!$B$23+(1-Inputs!$C$35)*E$5*Valuation!$B$26)/Inputs!$C$28 -> 38.294435 | F7: =(Inputs!$C$35*$A7*Valuation!$B$23+(1-Inputs!$C$35)*F$5*Valuation!$B$26)/Inputs!$C$28 -> 40.043121
A8: 1 | B8: =(Inputs!$C$35*$A8*Valuation!$B$23+(1-Inputs!$C$35)*B$5*Valuation!$B$26)/Inputs!$C$28 -> 35.166031 | C8: =(Inputs!$C$35*$A8*Valuation!$B$23+(1-Inputs!$C$35)*C$5*Valuation!$B$26)/Inputs!$C$28 -> 36.914717 | D8: =(Inputs!$C$35*$A8*Valuation!$B$23+(1-Inputs!$C$35)*D$5*Valuation!$B$26)/Inputs!$C$28 -> 38.663403 | E8: =(Inputs!$C$35*$A8*Valuation!$B$23+(1-Inputs!$C$35)*E$5*Valuation!$B$26)/Inputs!$C$28 -> 40.412089 | F8: =(Inputs!$C$35*$A8*Valuation!$B$23+(1-Inputs!$C$35)*F$5*Valuation!$B$26)/Inputs!$C$28 -> 42.160775
A9: 1.1 | B9: =(Inputs!$C$35*$A9*Valuation!$B$23+(1-Inputs!$C$35)*B$5*Valuation!$B$26)/Inputs!$C$28 -> 37.283685 | C9: =(Inputs!$C$35*$A9*Valuation!$B$23+(1-Inputs!$C$35)*C$5*Valuation!$B$26)/Inputs!$C$28 -> 39.032371 | D9: =(Inputs!$C$35*$A9*Valuation!$B$23+(1-Inputs!$C$35)*D$5*Valuation!$B$26)/Inputs!$C$28 -> 40.781057 | E9: =(Inputs!$C$35*$A9*Valuation!$B$23+(1-Inputs!$C$35)*E$5*Valuation!$B$26)/Inputs!$C$28 -> 42.529744 | F9: =(Inputs!$C$35*$A9*Valuation!$B$23+(1-Inputs!$C$35)*F$5*Valuation!$B$26)/Inputs!$C$28 -> 44.27843
A10: 1.2 | B10: =(Inputs!$C$35*$A10*Valuation!$B$23+(1-Inputs!$C$35)*B$5*Valuation!$B$26)/Inputs!$C$28 -> 39.40134 | C10: =(Inputs!$C$35*$A10*Valuation!$B$23+(1-Inputs!$C$35)*C$5*Valuation!$B$26)/Inputs!$C$28 -> 41.150026 | D10: =(Inputs!$C$35*$A10*Valuation!$B$23+(1-Inputs!$C$35)*D$5*Valuation!$B$26)/Inputs!$C$28 -> 42.898712 | E10: =(Inputs!$C$35*$A10*Valuation!$B$23+(1-Inputs!$C$35)*E$5*Valuation!$B$26)/Inputs!$C$28 -> 44.647398 | F10: =(Inputs!$C$35*$A10*Valuation!$B$23+(1-Inputs!$C$35)*F$5*Valuation!$B$26)/Inputs!$C$28 -> 46.396084
A13: DCF value per share vs. WACC (down) and terminal growth (across)
B14: 0 | C14: 0.01 | D14: 0.02 | E14: 0.03
A15: 0.06 | B15: =(Valuation!B44/(1+$A15)^1+Valuation!C44/(1+$A15)^2+Valuation!D44/(1+$A15)^3+Valuation!E44/(1+$A15)^4+Valuation!E44*(1+B$14)/($A15-B$14)/(1+$A15)^4-Valuation!$B$53+Valuation!$B$54)/Valuation!$B$7 -> 60.285651 | C15: =(Valuation!B44/(1+$A15)^1+Valuation!C44/(1+$A15)^2+Valuation!D44/(1+$A15)^3+Valuation!E44/(1+$A15)^4+Valuation!E44*(1+C$14)/($A15-C$14)/(1+$A15)^4-Valuation!$B$53+Valuation!$B$54)/Valuation!$B$7 -> 70.956397 | D15: =(Valuation!B44/(1+$A15)^1+Valuation!C44/(1+$A15)^2+Valuation!D44/(1+$A15)^3+Valuation!E44/(1+$A15)^4+Valuation!E44*(1+D$14)/($A15-D$14)/(1+$A15)^4-Valuation!$B$53+Valuation!$B$54)/Valuation!$B$7 -> 86.962517 | E15: =(Valuation!B44/(1+$A15)^1+Valuation!C44/(1+$A15)^2+Valuation!D44/(1+$A15)^3+Valuation!E44/(1+$A15)^4+Valuation!E44*(1+E$14)/($A15-E$14)/(1+$A15)^4-Valuation!$B$53+Valuation!$B$54)/Valuation!$B$7 -> 113.63938
A16: 0.07 | B16: =(Valuation!B44/(1+$A16)^1+Valuation!C44/(1+$A16)^2+Valuation!D44/(1+$A16)^3+Valuation!E44/(1+$A16)^4+Valuation!E44*(1+B$14)/($A16-B$14)/(1+$A16)^4-Valuation!$B$53+Valuation!$B$54)/Valuation!$B$7 -> 51.271859 | C16: =(Valuation!B44/(1+$A16)^1+Valuation!C44/(1+$A16)^2+Valuation!D44/(1+$A16)^3+Valuation!E44/(1+$A16)^4+Valuation!E44*(1+C$14)/($A16-C$14)/(1+$A16)^4-Valuation!$B$53+Valuation!$B$54)/Valuation!$B$7 -> 58.682112 | D16: =(Valuation!B44/(1+$A16)^1+Valuation!C44/(1+$A16)^2+Valuation!D44/(1+$A16)^3+Valuation!E44/(1+$A16)^4+Valuation!E44*(1+D$14)/($A16-D$14)/(1+$A16)^4-Valuation!$B$53+Valuation!$B$54)/Valuation!$B$7 -> 69.056466 | E16: =(Valuation!B44/(1+$A16)^1+Valuation!C44/(1+$A16)^2+Valuation!D44/(1+$A16)^3+Valuation!E44/(1+$A16)^4+Valuation!E44*(1+E$14)/($A16-E$14)/(1+$A16)^4-Valuation!$B$53+Valuation!$B$54)/Valuation!$B$7 -> 84.617998
A17: 0.08 | B17: =(Valuation!B44/(1+$A17)^1+Valuation!C44/(1+$A17)^2+Valuation!D44/(1+$A17)^3+Valuation!E44/(1+$A17)^4+Valuation!E44*(1+B$14)/($A17-B$14)/(1+$A17)^4-Valuation!$B$53+Valuation!$B$54)/Valuation!$B$7 -> 44.525835 | C17: =(Valuation!B44/(1+$A17)^1+Valuation!C44/(1+$A17)^2+Valuation!D44/(1+$A17)^3+Valuation!E44/(1+$A17)^4+Valuation!E44*(1+C$14)/($A17-C$14)/(1+$A17)^4-Valuation!$B$53+Valuation!$B$54)/Valuation!$B$7 -> 49.93057 | D17: =(Valuation!B44/(1+$A17)^1+Valuation!C44/(1+$A17)^2+Valuation!D44/(1+$A17)^3+Valuation!E44/(1+$A17)^4+Valuation!E44*(1+D$14)/($A17-D$14)/(1+$A17)^4-Valuation!$B$53+Valuation!$B$54)/Valuation!$B$7 -> 57.136883 | E17: =(Valuation!B44/(1+$A17)^1+Valuation!C44/(1+$A17)^2+Valuation!D44/(1+$A17)^3+Valuation!E44/(1+$A17)^4+Valuation!E44*(1+E$14)/($A17-E$14)/(1+$A17)^4-Valuation!$B$53+Valuation!$B$54)/Valuation!$B$7 -> 67.225721
A18: 0.09 | B18: =(Valuation!B44/(1+$A18)^1+Valuation!C44/(1+$A18)^2+Valuation!D44/(1+$A18)^3+Valuation!E44/(1+$A18)^4+Valuation!E44*(1+B$14)/($A18-B$14)/(1+$A18)^4-Valuation!$B$53+Valuation!$B$54)/Valuation!$B$7 -> 39.291153 | C18: =(Valuation!B44/(1+$A18)^1+Valuation!C44/(1+$A18)^2+Valuation!D44/(1+$A18)^3+Valuation!E44/(1+$A18)^4+Valuation!E44*(1+C$14)/($A18-C$14)/(1+$A18)^4-Valuation!$B$53+Valuation!$B$54)/Valuation!$B$7 -> 43.380196 | D18: =(Valuation!B44/(1+$A18)^1+Valuation!C44/(1+$A18)^2+Valuation!D44/(1+$A18)^3+Valuation!E44/(1+$A18)^4+Valuation!E44*(1+D$14)/($A18-D$14)/(1+$A18)^4-Valuation!$B$53+Valuation!$B$54)/Valuation!$B$7 -> 48.637537 | E18: =(Valuation!B44/(1+$A18)^1+Valuation!C44/(1+$A18)^2+Valuation!D44/(1+$A18)^3+Valuation!E44/(1+$A18)^4+Valuation!E44*(1+E$14)/($A18-E$14)/(1+$A18)^4-Valuation!$B$53+Valuation!$B$54)/Valuation!$B$7 -> 55.647325
A19: 0.1 | B19: =(Valuation!B44/(1+$A19)^1+Valuation!C44/(1+$A19)^2+Valuation!D44/(1+$A19)^3+Valuation!E44/(1+$A19)^4+Valuation!E44*(1+B$14)/($A19-B$14)/(1+$A19)^4-Valuation!$B$53+Valuation!$B$54)/Valuation!$B$7 -> 35.113979 | C19: =(Valuation!B44/(1+$A19)^1+Valuation!C44/(1+$A19)^2+Valuation!D44/(1+$A19)^3+Valuation!E44/(1+$A19)^4+Valuation!E44*(1+C$14)/($A19-C$14)/(1+$A19)^4-Valuation!$B$53+Valuation!$B$54)/Valuation!$B$7 -> 38.296807 | D19: =(Valuation!B44/(1+$A19)^1+Valuation!C44/(1+$A19)^2+Valuation!D44/(1+$A19)^3+Valuation!E44/(1+$A19)^4+Valuation!E44*(1+D$14)/($A19-D$14)/(1+$A19)^4-Valuation!$B$53+Valuation!$B$54)/Valuation!$B$7 -> 42.275341 | E19: =(Valuation!B44/(1+$A19)^1+Valuation!C44/(1+$A19)^2+Valuation!D44/(1+$A19)^3+Valuation!E44/(1+$A19)^4+Valuation!E44*(1+E$14)/($A19-E$14)/(1+$A19)^4-Valuation!$B$53+Valuation!$B$54)/Valuation!$B$7 -> 47.390599

Sheet Ratios
A1: Alamos Gold Inc. — Financial analysis ratios
A2: CFA L2 Financial Statement Analysis: DuPont, cash conversion, leverage and payout. Formulas on the Model sheet.
A4: Ratio | B4: Unit | C4: 2025A | D4: H1-26A | E4: H2-26E | F4: 2026E | G4: 2027E | H4: 2028E | I4: 2029E | J4: 2030E | K4: Reading
A5: AISC margin (% of gold price) | C5: =IFERROR(Model!C9/Model!C7,"") -> 0.5480427 | D5: =IFERROR(Model!D9/Model!D7,"") -> 0.61523605 | E5: =IFERROR(Model!E9/Model!E7,"") -> 0.55833333 | F5: =IFERROR(Model!F9/Model!F7,"") -> 0.58687941 | G5: =IFERROR(Model!G9/Model!G7,"") -> 0.6125 | H5: =IFERROR(Model!H9/Model!H7,"") -> 0.64473684 | I5: =IFERROR(Model!I9/Model!I7,"") -> 0.65277778 | J5: =IFERROR(Model!J9/Model!J7,"") -> 0.65714286
A6: Free cash flow conversion (FCF / OCF) | C6: =IFERROR(Model!C23/Model!C18,"") -> 0.44222306 | D6: =IFERROR(Model!D23/Model!D18,"") -> 0.51697238 | E6: =IFERROR(Model!E23/Model!E18,"") -> 0.19099111 | F6: =IFERROR(Model!F23/Model!F18,"") -> 0.332338 | G6: =IFERROR(Model!G23/Model!G18,"") -> 0.35245902 | H6: =IFERROR(Model!H23/Model!H18,"") -> 0.53076432 | I6: =IFERROR(Model!I23/Model!I18,"") -> 0.68751218 | J6: =IFERROR(Model!J23/Model!J18,"") -> 0.76436782
A7: Reinvestment rate ((growth capital + exploration) / OCF) | E7: =IFERROR((Model!E21+Model!E22)/Model!E18,"") -> 0.60527375 | G7: =IFERROR((Model!G21+Model!G22)/Model!G18,"") -> 0.45081967 | H7: =IFERROR((Model!H21+Model!H22)/Model!H18,"") -> 0.27251437 | I7: =IFERROR((Model!I21+Model!I22)/Model!I18,"") -> 0.10909799 | J7: =IFERROR((Model!J21+Model!J22)/Model!J18,"") -> 0.028735632
A8: Return on average equity | G8: =IFERROR(Model!G16/AVERAGE(Model!F30,Model!G30),"") -> 0.19700557 | H8: =IFERROR(Model!H16/AVERAGE(Model!G30,Model!H30),"") -> 0.19673222 | I8: =IFERROR(Model!I16/AVERAGE(Model!H30,Model!I30),"") -> 0.1778281 | J8: =IFERROR(Model!J16/AVERAGE(Model!I30,Model!J30),"") -> 0.16294156 | K8: Equity rolled forward from a Q1-26 proxy; directional only
A9: Dividend payout (DPS / EPS) | C9: =IFERROR(Model!C25/Model!C15,"") -> 0.071428571 | F9: =IFERROR(Model!F25/Model!F15,"") -> 0.072136783 | G9: =IFERROR(Model!G25/Model!G15,"") -> 0.062014815 | H9: =IFERROR(Model!H25/Model!H15,"") -> 0.051544781 | I9: =IFERROR(Model!I25/Model!I15,"") -> 0.047741958 | J9: =IFERROR(Model!J25/Model!J15,"") -> 0.044296296
A10: Net debt / OCF | F10: =IFERROR(Model!F29/Model!F18,"") -> -0.43126524 | G10: =IFERROR(Model!G29/Model!G18,"") -> -0.6289381 | H10: =IFERROR(Model!H29/Model!H18,"") -> -1.0154932 | I10: =IFERROR(Model!I29/Model!I18,"") -> -1.5819538 | J10: =IFERROR(Model!J29/Model!J18,"") -> -2.1906549

Sheet Comps
A1: Alamos Gold Inc. — Peer comparison
A2: Gold peers, Q2-26 annualized. Prices as of Oct 26, 2026.
A4: Company | B4: Ticker | C4: Price (US$) | D4: Mkt cap (US$B) | E4: P/E | F4: P/CF | G4: AISC (US$/oz) | H4: FCF yield
A5: Alamos Gold | B5: AGI | C5: 30.21 | D5: 12.6 | E5: 12.8 | F5: 13.7 | G5: 1728 | H5: 4.5%
A6: Agnico Eagle | B6: AEM | C6: 175.69 | D6: 88.2 | E6: 14.3 | F6: 10.3 | G6: 1459 | H6: 6.1%
A7: Kinross Gold | B7: KGC | C7: 22.45 | D7: 26.6 | E7: 7.9 | F7: 5.8 | G7: 1821 | H7: 10.9%
A9: Source: Company Q2-26 filings; Northwall calculations

Sheet Checks
A1: Alamos Gold Inc. — Model integrity checks
A2: Every check should read TRUE before anything is published.
A4: Check | B4: Model | C4: Expected | D4: Pass
A5: Price target equals the published target | B5: =Valuation!$B$34 -> 39 | C5: 39 | D5: =ABS(B5-C5)<=MAX(0.01,ABS(C5)*0.005) -> TRUE
A6: Rating equals the published rating | B6: =Valuation!$B$39 -> Buy | C6: Buy | D6: =B6=C6 -> TRUE
A7: NAV per share equals the published NAVPS | B7: =NAV!$B$18 -> 42.353085 | C7: 42.35 | D7: =ABS(B7-C7)<=MAX(0.01,ABS(C7)*0.005) -> TRUE
A8: 2026E adjusted EPS equals the published estimate | B8: =Model!$F$15 -> 2.2180085 | C8: 2.22 | D8: =ABS(B8-C8)<=MAX(0.01,ABS(C8)*0.005) -> TRUE
A9: 2027E CFPS equals the published estimate | B9: =Model!$G$19 -> 3.4973722 | C9: 3.5 | D9: =ABS(B9-C9)<=MAX(0.01,ABS(C9)*0.005) -> TRUE
A10: 2028E free cash flow equals the published estimate | B10: =Model!$H$23 -> 934.875 | C10: 934.88 | D10: =ABS(B10-C10)<=MAX(0.01,ABS(C10)*0.005) -> TRUE
A12: All checks pass | D12: =AND(D5:D10) -> TRUE

Sheet Log
A1: Model change log
A2: Newest first. One row per change; never delete rows.
A4: Date | B4: Version | C4: Change | D4: Effect on target
A5: 2026-10-27 | B5: v2026Q2 | C5: Model built on house template from Q2-26 filings; ties to the published 2026-10-27 report | D5: Target US$39, Buy
