Workbook

Sheet Cover
A1: NORTHWALL RESEARCH
A2: Franco-Nevada Corporation (FNV)
A3: Gold royalties and streaming · Analyst: Basel Al-Ghousein · Model version v2026Q2 · Built 2026-10-27
A5: Rating | B5: =Valuation!$B$39 -> Hold
A6: Price target (USD) | B6: =Valuation!$B$34 -> 250
A7: Share price (USD), NYSE close Oct 26, 2026 (Upstox) | B7: =Valuation!$B$5 -> 230.76
A8: Implied all-in return | B8: =Valuation!$B$38 -> 0.09100364
A9: Valuation method 1 | B9: =Valuation!$B$25 -> 277.76176
A10: Valuation method 2 | B10: =Valuation!$B$28 -> 224.93758
A11: DCF cross-check per share | B11: =Valuation!$B$55 -> 150.1754
A12: Cost of equity (CAPM) | B12: =Valuation!$B$16 -> 0.0787
A13: Market-implied growth | B13: =Valuation!$B$61 -> 0.039709259
A14: All integrity checks pass | B14: =IF(Checks!$D$12,"Yes","NO - see Checks") -> Yes
A16: Colour code
A17: Blue: typed input with a source (Inputs sheet only)
A18: Black: formula
A19: Green: link to another sheet
A20: Yellow fill: key assumption or output
A22: Sheets
A23: Inputs | B23: Every typed number, with its source
A24: Model | B24: Operations and financials, H1 actual + H2 estimate
A25: Valuation | B25: Target methods, CAPM/WACC, DCF, reverse DCF, residual income, justified P/E
A26: NAV | B26: Asset-life cash flows (resource names)
A27: Sensitivity | B27: Target and DCF grids
A28: Ratios | B28: DuPont, cash conversion, leverage, payout
A29: Comps | B29: Peer table
A30: Checks | B30: Integrity checks; all must be TRUE
A31: Log | B31: Every change, dated, with its reason

Sheet Inputs
A1: Franco-Nevada Corporation (FNV) — Inputs
A2: Every typed number in the model lives here, in blue, with its source. Change inputs here only.
A4: House price deck (from data/price_deck.yaml)
A5: Input | B5: Unit | C5: 2025A | D5: H1-26A | E5: H2-26E | F5: 2026E | G5: 2027E | H5: 2028E | I5: 2029E | J5: 2030E | K5: Source
A6: Gold price, house deck | B6: US$/oz | E6: 4200 | G6: 4000 | H6: 3800 | I6: 3600 | J6: 3500 | K6: Northwall deck: Q3-26 ~4,350 and Q4-26 4,050 (avg 4,200); spot ~US$4,000 on Oct 23, 2026 (pricegold.net); steps to a 3,500 long-term real price
A8: Company drivers by period
A9: Input | B9: Unit | C9: 2025A | D9: H1-26A | E9: H2-26E | F9: 2026E | G9: 2027E | H9: 2028E | I9: 2029E | J9: 2030E | K9: Source
A10: GEOs sold | B10: koz | C10: 519.106 | D10: 268.758 | E10: 283 | G10: 572 | H10: 570 | I10: 585 | J10: 600 | K10: 2025A: 2025 results (Mar 10, 2026). H1-26A: Q2-26 release (Aug 11, 2026). H2-26E: Northwall, Q3 138k + Q4 145k incl. Cobre stockpile deliveries. 2027E+: Northwall, inside the 555-615k 2030 outlook
A11: Revenue, reported | B11: US$M | C11: 1822.8 | D11: 1231.6 | K11: 2025 results; Q2-26 release income statement
A12: Costs of sales, reported | B12: US$M | C12: 168.8 | D12: 92.4 | K12: 2025 results; Q2-26 release income statement
A13: G&A + share-based comp, reported | B13: US$M | C13: 35.3 | D13: 19.7 | K13: 2025A G&A only; H1-26A G&A 17.0 + SBC 2.7 (Q2-26 release)
A14: Adjusted EBITDA, reported | B14: US$M | C14: 1656.1 | D14: 1121.6 | K14: 2025 results; Q2-26 release non-GAAP reconciliation
A15: Depletion and depreciation, reported | B15: US$M | C15: 306.7 | D15: 161.9 | K15: 2025 results; Q2-26 release
A16: Adjusted net income, reported | B16: US$M | C16: 1075.2 | D16: 807.5 | K16: 2025 results; Q2-26 release (includes the US$63.8M buy-back gain, no longer excluded)
A17: Operating cash flow, reported | B17: US$M | C17: 1493.7 | D17: 1002.9 | K17: 2025 results; Q2-26 release cash flow statement
A18: Cash, reported | B18: US$M | C18: 670.9 | D18: 1014.2 | K18: Balance sheets Dec 31, 2025 and Jun 30, 2026
A19: Shareholders' equity, reported | B19: US$M | C19: 7635.3 | D19: 8240.7 | K19: Balance sheets Dec 31, 2025 and Jun 30, 2026
A20: Depletion per GEO | B20: US$/oz | E20: 635 | G20: 645 | H20: 650 | I20: 655 | J20: 660 | K20: Northwall: Q2-26 run-rate US$634/GEO (84.0 / 132.4k), rising with new assets
A21: Finance income | B21: US$M | E21: 14 | G21: 30 | H21: 30 | I21: 30 | J21: 30 | K21: Northwall: H1-26 US$12.3M run-rate
A22: G&A + share-based comp | B22: US$M | E22: 21 | G22: 43.26 | H22: 44.56 | I22: 45.9 | J22: 47.27 | K22: Northwall: US$42M a year growing 3%
A23: Acquisitions | B23: US$M | E23: 60 | G23: 500 | H23: 500 | I23: 500 | J23: 500 | K23: Northwall: H2 includes Comet Vale (US$8.4M); US$500M a year thereafter, no production credited
A24: Basic shares | B24: M | C24: 192.7 | D24: 192.8 | E24: 193 | F24: 193 | G24: 193.4 | H24: 193.8 | I24: 194.2 | J24: 194.6 | K24: Weighted basic shares per filings; DRIP issuance thereafter
A25: Dividend per share | B25: US$ | C25: 1.52 | D25: 0.88 | E25: 0.88 | G25: 1.92 | H25: 2.08 | I25: 2.24 | J25: 2.4 | K25: US$0.38 x 4 (2025); US$0.44 quarterly (2026); Northwall +US$0.16/yr
A27: Scalar inputs: market data, operating assumptions, valuation parameters
A28: Input | B28: Unit | C28: Value | K28: Source
A29: Share price | C29: 230.76 | K29: NYSE close Oct 26, 2026 (Upstox)
A30: Model currency per listing currency | C30: 1 | K30: Same currency
A31: Basic shares outstanding | B31: M | C31: 192.9 | K31: Latest company filing
A32: Net debt at last balance sheet (negative = net cash) | B32: M | C32: -1014.2 | K32: Latest quarterly filing
A33: Equity beta | C33: 0.58 | K33: Beta 0.58 (Motley Fool, Oct 2026)
A34: Pre-tax cost of debt | C34: 0.055 | K34: Northwall assumption: credit facility pricing
A35: Effective tax rate | C35: 0.22 | K35: H1-26: 231.2 / 1,053.8 = 21.9%
A36: Gross debt | B36: M | C36: 0 | K36: Latest quarterly filing
A37: Weight on valuation method 1 | C37: 0.5 | K37: Northwall method: equal weight
A38: Target multiple, method 1 | C38: 2 | K38: Northwall: premium for diversification and a debt-free balance sheet
A39: Target multiple, method 2 | C39: 25 | K39: Northwall: near trailing P/CF of ~25x (Morningstar)
A40: Next-12-month dividend per share | C40: 1.76 | K40: US$0.44 quarterly (Q2-26 release)
A41: Target rounding increment | C41: 5 | K41: House style
A42: Buy threshold: expected 12-month total return | C42: 0.15 | K42: Northwall rating definitions
A43: Terminal growth for DCF cross-check (nominal) | C43: 0.02 | K43: Northwall: 0% for depleting oil assets, 2% for long-life gold portfolios
...

Sheet Model
A1: Franco-Nevada Corporation — Operating and financial model (USD millions unless noted)
A2: H1-26A = reported six months; H2-26E = Northwall estimate; 2026E = H1 + H2. All cells are formulas.
A4: Line | B4: Unit | C4: 2025A | D4: H1-26A | E4: H2-26E | F4: 2026E | G4: 2027E | H4: 2028E | I4: 2029E | J4: 2030E | K4: Method
A5: Volumes and price
A6: GEOs sold | B6: koz | C6: =Inputs!C10 -> 519.106 | D6: =Inputs!D10 -> 268.758 | E6: =Inputs!E10 -> 283 | F6: =D6+E6 -> 551.758 | G6: =Inputs!G10 -> 572 | H6: =Inputs!H10 -> 570 | I6: =Inputs!I10 -> 585 | J6: =Inputs!J10 -> 600
A7: Gold price, house deck | B7: US$/oz | E7: =Inputs!E6 -> 4200 | G7: =Inputs!G6 -> 4000 | H7: =Inputs!H6 -> 3800 | I7: =Inputs!I6 -> 3600 | J7: =Inputs!J6 -> 3500
A8: Revenue per GEO | B8: US$/oz | C8: =C10/C6*1000 -> 3511.4216 | D8: =D10/D6*1000 -> 4582.5613 | E8: =E10/E6*1000 -> 4074 | F8: =F10/F6*1000 -> 4321.7171 | G8: =G10/G6*1000 -> 3880 | H8: =H10/H6*1000 -> 3686 | I8: =I10/I6*1000 -> 3492 | J8: =J10/J6*1000 -> 3395 | K8: Realized revenue per GEO
A9: Income statement
A10: Revenue | B10: US$M | C10: =Inputs!C11 -> 1822.8 | D10: =Inputs!D11 -> 1231.6 | E10: =E6*E7*Inputs!$C$45/1000 -> 1152.942 | F10: =D10+E10 -> 2384.542 | G10: =G6*G7*Inputs!$C$45/1000 -> 2219.36 | H10: =H6*H7*Inputs!$C$45/1000 -> 2101.02 | I10: =I6*I7*Inputs!$C$45/1000 -> 2042.82 | J10: =J6*J7*Inputs!$C$45/1000 -> 2037 | K10: GEOs x deck gold x realization
A11: Costs of sales (excl. depletion) | B11: US$M | C11: =Inputs!C12 -> 168.8 | D11: =Inputs!D12 -> 92.4 | E11: =E10*Inputs!$C$46 -> 89.929476 | F11: =D11+E11 -> 182.32948 | G11: =G10*Inputs!$C$46 -> 173.11008 | H11: =H10*Inputs!$C$46 -> 163.87956 | I11: =I10*Inputs!$C$46 -> 159.33996 | J11: =J10*Inputs!$C$46 -> 158.886
A12: G&A and share-based compensation | B12: US$M | C12: =Inputs!C13 -> 35.3 | D12: =Inputs!D13 -> 19.7 | E12: =Inputs!E22 -> 21 | F12: =D12+E12 -> 40.7 | G12: =Inputs!G22 -> 43.26 | H12: =Inputs!H22 -> 44.56 | I12: =Inputs!I22 -> 45.9 | J12: =Inputs!J22 -> 47.27
A13: Adjusted EBITDA | B13: US$M | C13: =Inputs!C14 -> 1656.1 | D13: =Inputs!D14 -> 1121.6 | E13: =E10-E11-E12 -> 1042.0125 | F13: =D13+E13 -> 2163.6125 | G13: =G10-G11-G12 -> 2002.9899 | H13: =H10-H11-H12 -> 1892.5804 | I13: =I10-I11-I12 -> 1837.58 | J13: =J10-J11-J12 -> 1830.844
A14: Adjusted EBITDA margin | B14: % | C14: =C13/C10 -> 0.90854729 | D14: =D13/D10 -> 0.91068529 | E14: =E13/E10 -> 0.90378573 | F14: =F13/F10 -> 0.9073493 | G14: =G13/G10 -> 0.90250789 | H14: =H13/H10 -> 0.90079125 | I14: =I13/I10 -> 0.89953106 | J14: =J13/J10 -> 0.89879431
A15: Depletion and depreciation | B15: US$M | C15: =Inputs!C15 -> 306.7 | D15: =Inputs!D15 -> 161.9 | E15: =E6*Inputs!E20/1000 -> 179.705 | F15: =D15+E15 -> 341.605 | G15: =G6*Inputs!G20/1000 -> 368.94 | H15: =H6*Inputs!H20/1000 -> 370.5 | I15: =I6*Inputs!I20/1000 -> 383.175 | J15: =J6*Inputs!J20/1000 -> 396
A16: Finance income | B16: US$M | E16: =Inputs!E21 -> 14 | G16: =Inputs!G21 -> 30 | H16: =Inputs!H21 -> 30 | I16: =Inputs!I21 -> 30 | J16: =Inputs!J21 -> 30
A17: Adjusted pre-tax income | B17: US$M | E17: =E13-E15+E16 -> 876.30752 | G17: =G13-G15+G16 -> 1664.0499 | H17: =H13-H15+H16 -> 1552.0804 | I17: =I13-I15+I16 -> 1484.405 | J17: =J13-J15+J16 -> 1464.844
A18: Income taxes | B18: US$M | E18: =E17*Inputs!$C$35 -> 192.78766 | G18: =G17*Inputs!$C$35 -> 366.09098 | H18: =H17*Inputs!$C$35 -> 341.4577 | I18: =I17*Inputs!$C$35 -> 326.56911 | J18: =J17*Inputs!$C$35 -> 322.26568
A19: Adjusted net income | B19: US$M | C19: =Inputs!C16 -> 1075.2 | D19: =Inputs!D16 -> 807.5 | E19: =E17-E18 -> 683.51987 | F19: =D19+E19 -> 1491.0199 | G19: =G17-G18 -> 1297.9589 | H19: =H17-H18 -> 1210.6227 | I19: =I17-I18 -> 1157.8359 | J19: =J17-J18 -> 1142.5783
A20: Basic shares | B20: M | C20: =Inputs!C24 -> 192.7 | D20: =Inputs!D24 -> 192.8 | E20: =Inputs!E24 -> 193 | F20: =Inputs!F24 -> 193 | G20: =Inputs!G24 -> 193.4 | H20: =Inputs!H24 -> 193.8 | I20: =Inputs!I24 -> 194.2 | J20: =Inputs!J24 -> 194.6
A21: Adjusted EPS | B21: US$ | C21: =C19/C20 -> 5.5796575 | D21: =D19/D20 -> 4.188278 | E21: =E19/E20 -> 3.5415537 | F21: =F19/F20 -> 7.7254915 | G21: =G19/G20 -> 6.7112665 | H21: =H19/H20 -> 6.2467634 | I21: =I19/I20 -> 5.96208 | J21: =J19/J20 -> 5.8714199
A22: Cash flow
A23: Operating cash flow | B23: US$M | C23: =Inputs!C17 -> 1493.7 | D23: =Inputs!D17 -> 1002.9 | E23: =E13+E16-Inputs!$C$47*E18 -> 901.7824 | F23: =D23+E23 -> 1904.6824 | G23: =G13+G16-Inputs!$C$47*G18 -> 1740.1171 | H23: =H13+H16-Inputs!$C$47*H18 -> 1649.4143 | I23: =I13+I16-Inputs!$C$47*I18 -> 1606.3248 | J23: =J13+J16-Inputs!$C$47*J18 -> 1603.0315 | K23: EBITDA + finance income - cash taxes
A24: Cash flow per share | B24: US$ | C24: =C23/C20 -> 7.7514271 | D24: =D23/D20 -> 5.2017635 | E24: =E23/E20 -> 4.6724477 | F24: =F23/F20 -> 9.8688207 | G24: =G23/G20 -> 8.9975033 | H24: =H23/H20 -> 8.5109096 | I24: =I23/I20 -> 8.2714972 | J24: =J23/J20 -> 8.2375717
A25: Free cash flow to the firm (pre-acquisitions) | B25: US$M | G25: =G23 -> 1740.1171 | H25: =H23 -> 1649.4143 | I25: =I23 -> 1606.3248 | J25: =J23 -> 1603.0315 | K25: No sustaining capital; acquisitions are discretionary growth
A26: Dividend per share | B26: US$ | C26: =Inputs!C25 -> 1.52 | D26: =Inputs!D25 -> 0.88 | E26: =Inputs!E25 -> 0.88 | F26: =D26+E26 -> 1.76 | G26: =Inputs!G25 -> 1.92 | H26: =Inputs!H25 -> 2.08 | I26: =Inputs!I25 -> 2.24 | J26: =Inputs!J25 -> 2.4
A27: Dividends paid | B27: US$M | E27: =E26*E20 -> 169.84 | G27: =G26*G20 -> 371.328 | H27: =H26*H20 -> 403.104 | I27: =I26*I20 -> 435.008 | J27: =J26*J20 -> 467.04
A28: Acquisitions of royalties and streams | B28: US$M | E28: =Inputs!E23 -> 60 | G28: =Inputs!G23 -> 500 | H28: =Inputs!H23 -> 500 | I28: =Inputs!I23 -> 500 | J28: =Inputs!J23 -> 500 | K28: No production credit taken for unannounced deals
A29: Balance sheet
A30: Cash and equivalents, period end | B30: US$M | C30: =Inputs!C18 -> 670.9 | D30: =Inputs!D18 -> 1014.2 | E30: =D30+E23-E27-E28 -> 1686.1424 | F30: =E30 -> 1686.1424 | G30: =F30+G23-G27-G28 -> 2554.9315 | H30: =G30+H23-H27-H28 -> 3301.2418 | I30: =H30+I23-I27-I28 -> 3972.5586 | J30: =I30+J23-J27-J28 -> 4608.55
A31: Net debt (negative = net cash) | B31: US$M | C31: =-C30 -> -670.9 | D31: =-D30 -> -1014.2 | E31: =-E30 -> -1686.1424 | F31: =-F30 -> -1686.1424 | G31: =-G30 -> -2554.9315 | H31: =-H30 -> -3301.2418 | I31: =-I30 -> -3972.5586 | J31: =-J30 -> -4608.55 | K31: No debt drawn
A32: Shareholders' equity, period end | B32: US$M | C32: =Inputs!C19 -> 7635.3 | D32: =Inputs!D19 -> 8240.7 | E32: =D32+E19-E27 -> 8754.3799 | F32: =E32 -> 8754.3799 | G32: =F32+G19-G27 -> 9681.0108 | H32: =G32+H19-H27 -> 10488.53 | I32: =H32+I19-I27 -> 11211.357 | J32: =I32+J19-J27 -> 11886.896 | K32: Rolled forward: + NI - dividends (OCI ignored)

Sheet Valuation
A1: Franco-Nevada Corporation — Valuation and price target
A2: Target methods first; CFA Level II cross-checks (DCF, reverse DCF, residual income, justified P/E) follow.
A4: Market data
A5: Share price (USD) | B5: =Inputs!$C$29 -> 230.76 | C5: NYSE close Oct 26, 2026 (Upstox)
A6: Share price in model currency (USD) | B6: =Inputs!$C$29*Inputs!$C$30 -> 230.76 | C6: Converted when the listing currency differs from the reporting currency
A7: Basic shares outstanding (M) | B7: =Inputs!$C$31 -> 192.9
A8: Market capitalization (M) | B8: =Valuation!$B$6*Valuation!$B$7 -> 44513.604
A9: Net debt (cash) at last balance sheet (M) | B9: =Inputs!$C$32 -> -1014.2 | C9: Negative = net cash
A10: Enterprise value (M) | B10: =Valuation!$B$8+Valuation!$B$9 -> 43499.404 | C10: Market cap + net debt
A12: Required return on equity (CAPM) and WACC — CFA L2 Equity: Return Concepts; Corporate Issuers: Cost of Capital
A13: Risk-free rate (US 10-yr) | B13: =Inputs!$C$59 -> 0.0497 | C13: House deck
A14: Equity beta | B14: =Inputs!$C$33 -> 0.58 | C14: Beta 0.58 (Motley Fool, Oct 2026)
A15: Equity risk premium | B15: =Inputs!$C$60 -> 0.05 | C15: House deck
A16: Cost of equity: rf + beta x ERP | B16: =Valuation!$B$13+Valuation!$B$14*Valuation!$B$15 -> 0.0787 | C16: CAPM
A17: Pre-tax cost of debt | B17: =Inputs!$C$34 -> 0.055 | C17: Northwall assumption: credit facility pricing
A18: Marginal tax rate | B18: =Inputs!$C$35 -> 0.22
A19: Debt weight: D / (D + E), market values | B19: =Inputs!$C$36/(Inputs!$C$36+Valuation!$B$8) -> 0 | C19: Gross debt at market cap
A20: WACC | B20: =Valuation!$B$16*(1-Valuation!$B$19)+Valuation!$B$17*(1-Valuation!$B$18)*Valuation!$B$19 -> 0.0787 | C20: ke x E/V + kd x (1 - t) x D/V
A22: Target method 1: P/NAV — method 2: P/CF
A23: NAV per share (NAV sheet) | B23: =NAV!$B$22 -> 138.88088
A24: Target P/NAV multiple | B24: =Inputs!$C$38 -> 2 | C24: Northwall: premium for diversification and a debt-free balance sheet
A25: Method 1 value per share | B25: =Valuation!$B$23*Valuation!$B$24 -> 277.76176
A26: Cash flow per share, 2027E | B26: =Model!$G$24 -> 8.9975033
A27: Target P/CF multiple, 2027E | B27: =Inputs!$C$39 -> 25 | C27: Northwall: near trailing P/CF of ~25x (Morningstar)
A28: Method 2 value per share | B28: =Valuation!$B$26*Valuation!$B$27 -> 224.93758
A29: Price target and rating
A30: Weight on method 1 | B30: =Inputs!$C$37 -> 0.5
A31: Weight on method 2 | B31: =1-Inputs!$C$37 -> 0.5
A32: Blended value per share (USD) | B32: =Valuation!$B$30*Valuation!$B$25+Valuation!$B$31*Valuation!$B$28 -> 251.34967
A33: Blended value per share (USD) | B33: =Valuation!$B$32/Inputs!$C$30 -> 251.34967 | C33: Converted to listing currency
A34: 12-month price target (USD), rounded | B34: =MROUND(Valuation!$B$33,Inputs!$C$41) -> 250 | C34: Rounded to the house increment
A35: Next-12-month dividend per share (listing currency) | B35: =Inputs!$C$40 -> 1.76 | C35: US$0.44 quarterly (Q2-26 release)
A36: Implied price return | B36: =Valuation!$B$34/Valuation!$B$5-1 -> 0.083376668
A37: Dividend yield | B37: =Valuation!$B$35/Valuation!$B$5 -> 0.0076269717
A38: Implied all-in return | B38: =Valuation!$B$36+Valuation!$B$37 -> 0.09100364 | C38: Rating bands: Buy > 15%, Hold 0–15%, Sell < 0%
A39: Rating | B39: =IF(Valuation!$B$38>Inputs!$C$42,"Buy",IF(Valuation!$B$38>=0,"Hold","Sell")) -> Hold
A41: Cross-check 1: two-stage FCFF DCF — CFA L2 Equity: Free Cash Flow Valuation
A42: Valuation date: Dec 31, 2026. FCFF discounted at WACC, end-year; Gordon growth terminal value on 2030E FCFF.
A43: Year | B43: 2027E | C43: 2028E | D43: 2029E | E43: 2030E
A44: FCFF (USD M) | B44: =Model!$G$25 -> 1740.1171 | C44: =Model!$H$25 -> 1649.4143 | D44: =Model!$I$25 -> 1606.3248 | E44: =Model!$J$25 -> 1603.0315
...

Sheet NAV
A1: Franco-Nevada Corporation — Net asset value (5% real, Dec 31, 2026)
A2: Portfolio GEOs per Model to 2030E, flat to 2035, then a 4% annual decline to 2060.
A4: Year | C4: 2027 | D4: 2028 | E4: 2029 | F4: 2030 | G4: 2031 | H4: 2032 | I4: 2033 | J4: 2034 | K4: 2035 | L4: 2036 | M4: 2037 | N4: 2038 | O4: 2039 | P4: 2040 | Q4: 2041 | R4: 2042 | S4: 2043 | T4: 2044 | U4: 2045 | V4: 2046 | W4: 2047 | X4: 2048 | Y4: 2049 | Z4: 2050 | AA4: 2051 | AB4: 2052 | AC4: 2053 | AD4: 2054 | AE4: 2055 | AF4: 2056 | AG4: 2057 | AH4: 2058 | AI4: 2059 | AJ4: 2060
A5: GEOs | B5: koz | C5: =Model!$G$6 -> 572 | D5: =Model!$H$6 -> 570 | E5: =Model!$I$6 -> 585 | F5: =Model!$J$6 -> 600 | G5: =Inputs!$C$48 -> 600 | H5: =Inputs!$C$48 -> 600 | I5: =Inputs!$C$48 -> 600 | J5: =Inputs!$C$48 -> 600 | K5: =Inputs!$C$48 -> 600 | L5: =K5*(1-Inputs!$C$49) -> 576 | M5: =L5*(1-Inputs!$C$49) -> 552.96 | N5: =M5*(1-Inputs!$C$49) -> 530.8416 | O5: =N5*(1-Inputs!$C$49) -> 509.60794 | P5: =O5*(1-Inputs!$C$49) -> 489.22362 | Q5: =P5*(1-Inputs!$C$49) -> 469.65467 | R5: =Q5*(1-Inputs!$C$49) -> 450.86849 | S5: =R5*(1-Inputs!$C$49) -> 432.83375 | ... AJ5: =AI5*(1-Inputs!$C$49) -> 216.23803
A6: Gold price | B6: US$/oz | C6: =Inputs!G6 -> 4000 | D6: =Inputs!H6 -> 3800 | E6: =Inputs!I6 -> 3600 | F6: =Inputs!J6 -> 3500 | G6: =Inputs!$C$58 -> 3500 | H6: =Inputs!$C$58 -> 3500 | I6: =Inputs!$C$58 -> 3500 | J6: =Inputs!$C$58 -> 3500 | K6: =Inputs!$C$58 -> 3500 | L6: =Inputs!$C$58 -> 3500 | M6: =Inputs!$C$58 -> 3500 | N6: =Inputs!$C$58 -> 3500 | ... AJ6: =Inputs!$C$58 -> 3500
A7: EBITDA | B7: US$M | C7: =C5*C6*Inputs!$C$45/1000*(1-Inputs!$C$46)-Inputs!$C$50 -> 2004.2499 | D7: =D5*D6*Inputs!$C$45/1000*(1-Inputs!$C$46)-Inputs!$C$50 -> 1895.1404 | E7: =E5*E6*Inputs!$C$45/1000*(1-Inputs!$C$46)-Inputs!$C$50 -> 1841.48 | F7: =F5*F6*Inputs!$C$45/1000*(1-Inputs!$C$46)-Inputs!$C$50 -> 1836.114 | G7: =G5*G6*Inputs!$C$45/1000*(1-Inputs!$C$46)-Inputs!$C$50 -> 1836.114 | H7: =H5*H6*Inputs!$C$45/1000*(1-Inputs!$C$46)-Inputs!$C$50 -> 1836.114 | I7: =I5*I6*Inputs!$C$45/1000*(1-Inputs!$C$46)-Inputs!$C$50 -> 1836.114 | J7: =J5*J6*Inputs!$C$45/1000*(1-Inputs!$C$46)-Inputs!$C$50 -> 1836.114 | ... AJ7: =AJ5*AJ6*Inputs!$C$45/1000*(1-Inputs!$C$46)-Inputs!$C$50 -> 634.86612
A8: After-tax cash flow | B8: US$M | C8: =C7*(1-Inputs!$C$51) -> 1623.4424 | D8: =D7*(1-Inputs!$C$51) -> 1535.0638 | E8: =E7*(1-Inputs!$C$51) -> 1491.5988 | F8: =F7*(1-Inputs!$C$51) -> 1487.2523 | G8: =G7*(1-Inputs!$C$51) -> 1487.2523 | H8: =H7*(1-Inputs!$C$51) -> 1487.2523 | I8: =I7*(1-Inputs!$C$51) -> 1487.2523 | J8: =J7*(1-Inputs!$C$51) -> 1487.2523 | ... AJ8: =AJ7*(1-Inputs!$C$51) -> 514.24156
A9: Discount factor (mid-year) | C9: =1/(1+Inputs!$C$52)^(2027-2026-0.5) -> 0.97590007 | D9: =1/(1+Inputs!$C$52)^(2028-2026-0.5) -> 0.92942864 | E9: =1/(1+Inputs!$C$52)^(2029-2026-0.5) -> 0.88517013 | F9: =1/(1+Inputs!$C$52)^(2030-2026-0.5) -> 0.84301918 | G9: =1/(1+Inputs!$C$52)^(2031-2026-0.5) -> 0.80287541 | H9: =1/(1+Inputs!$C$52)^(2032-2026-0.5) -> 0.76464324 | I9: =1/(1+Inputs!$C$52)^(2033-2026-0.5) -> 0.72823166 | J9: =1/(1+Inputs!$C$52)^(2034-2026-0.5) -> 0.69355396 | K9: =1/(1+Inputs!$C$52)^(2035-2026-0.5) -> 0.66052758 | L9: =1/(1+Inputs!$C$52)^(2036-2026-0.5) -> 0.62907389 | M9: =1/(1+Inputs!$C$52)^(2037-2026-0.5) -> 0.59911799 | N9: =1/(1+Inputs!$C$52)^(2038-2026-0.5) -> 0.57058856 | O9: =1/(1+Inputs!$C$52)^(2039-2026-0.5) -> 0.54341768 | P9: =1/(1+Inputs!$C$52)^(2040-2026-0.5) -> 0.51754064 | Q9: =1/(1+Inputs!$C$52)^(2041-2026-0.5) -> 0.49289585 | R9: =1/(1+Inputs!$C$52)^(2042-2026-0.5) -> 0.46942462 | S9: =1/(1+Inputs!$C$52)^(2043-2026-0.5) -> 0.44707107 | T9: =1/(1+Inputs!$C$52)^(2044-2026-0.5) -> 0.42578197 | U9: =1/(1+Inputs!$C$52)^(2045-2026-0.5) -> 0.40550664 | V9: =1/(1+Inputs!$C$52)^(2046-2026-0.5) -> 0.3861968 | W9: =1/(1+Inputs!$C$52)^(2047-2026-0.5) -> 0.36780647 | X9: =1/(1+Inputs!$C$52)^(2048-2026-0.5) -> 0.35029188 | Y9: =1/(1+Inputs!$C$52)^(2049-2026-0.5) -> 0.33361131 | Z9: =1/(1+Inputs!$C$52)^(2050-2026-0.5) -> 0.31772506 | AA9: =1/(1+Inputs!$C$52)^(2051-2026-0.5) -> 0.3025953 | AB9: =1/(1+Inputs!$C$52)^(2052-2026-0.5) -> 0.288186 | AC9: =1/(1+Inputs!$C$52)^(2053-2026-0.5) -> 0.27446285 | AD9: =1/(1+Inputs!$C$52)^(2054-2026-0.5) -> 0.26139319 | AE9: =1/(1+Inputs!$C$52)^(2055-2026-0.5) -> 0.2489459 | AF9: =1/(1+Inputs!$C$52)^(2056-2026-0.5) -> 0.23709133 | AG9: =1/(1+Inputs!$C$52)^(2057-2026-0.5) -> 0.22580127 | AH9: =1/(1+Inputs!$C$52)^(2058-2026-0.5) -> 0.21504883 | AI9: =1/(1+Inputs!$C$52)^(2059-2026-0.5) -> 0.20480841 | AJ9: =1/(1+Inputs!$C$52)^(2060-2026-0.5) -> 0.19505563
A10: Present value | B10: US$M | C10: =C8*C9 -> 1584.3176 | D10: =D8*D9 -> 1426.7322 | E10: =E8*E9 -> 1320.3187 | F10: =F8*F9 -> 1253.7822 | G10: =G8*G9 -> 1194.0783 | H10: =H8*H9 -> 1137.2175 | I10: =I8*I9 -> 1083.0642 | J10: =J8*J9 -> 1031.4898 | ... AJ10: =AJ8*AJ9 -> 100.30571
A11: Cobre Panamá restart cash flow (unrisked) | B11: US$M | C11: =IF(AND(2027>=Inputs!$C$53,2027<=2050),Inputs!$C$54*Inputs!$C$58*Inputs!$C$45/1000*(1-Inputs!$C$46)*(1-Inputs!$C$51),0) -> 0 | D11: =IF(AND(2028>=Inputs!$C$53,2028<=2050),Inputs!$C$54*Inputs!$C$58*Inputs!$C$45/1000*(1-Inputs!$C$46)*(1-Inputs!$C$51),0) -> 0 | E11: =IF(AND(2029>=Inputs!$C$53,2029<=2050),Inputs!$C$54*Inputs!$C$58*Inputs!$C$45/1000*(1-Inputs!$C$46)*(1-Inputs!$C$51),0) -> 380.31808 | F11: =IF(AND(2030>=Inputs!$C$53,2030<=2050),Inputs!$C$54*Inputs!$C$58*Inputs!$C$45/1000*(1-Inputs!$C$46)*(1-Inputs!$C$51),0) -> 380.31808 | G11: =IF(AND(2031>=Inputs!$C$53,2031<=2050),Inputs!$C$54*Inputs!$C$58*Inputs!$C$45/1000*(1-Inputs!$C$46)*(1-Inputs!$C$51),0) -> 380.31808 | H11: =IF(AND(2032>=Inputs!$C$53,2032<=2050),Inputs!$C$54*Inputs!$C$58*Inputs!$C$45/1000*(1-Inputs!$C$46)*(1-Inputs!$C$51),0) -> 380.31808 | I11: =IF(AND(2033>=Inputs!$C$53,2033<=2050),Inputs!$C$54*Inputs!$C$58*Inputs!$C$45/1000*(1-Inputs!$C$46)*(1-Inputs!$C$51),0) -> 380.31808 | J11: =IF(AND(2034>=Inputs!$C$53,2034<=2050),Inputs!$C$54*Inputs!$C$58*Inputs!$C$45/1000*(1-Inputs!$C$46)*(1-Inputs!$C$51),0) -> 380.31808 | K11: =IF(AND(2035>=Inputs!$C$53,2035<=2050),Inputs!$C$54*Inputs!$C$58*Inputs!$C$45/1000*(1-Inputs!$C$46)*(1-Inputs!$C$51),0) -> 380.31808 | L11: =IF(AND(2036>=Inputs!$C$53,2036<=2050),Inputs!$C$54*Inputs!$C$58*Inputs!$C$45/1000*(1-Inputs!$C$46)*(1-Inputs!$C$51),0) -> 380.31808 | M11: =IF(AND(2037>=Inputs!$C$53,2037<=2050),Inputs!$C$54*Inputs!$C$58*Inputs!$C$45/1000*(1-Inputs!$C$46)*(1-Inputs!$C$51),0) -> 380.31808 | N11: =IF(AND(2038>=Inputs!$C$53,2038<=2050),Inputs!$C$54*Inputs!$C$58*Inputs!$C$45/1000*(1-Inputs!$C$46)*(1-Inputs!$C$51),0) -> 380.31808 | O11: =IF(AND(2039>=Inputs!$C$53,2039<=2050),Inputs!$C$54*Inputs!$C$58*Inputs!$C$45/1000*(1-Inputs!$C$46)*(1-Inputs!$C$51),0) -> 380.31808 | P11: =IF(AND(2040>=Inputs!$C$53,2040<=2050),Inputs!$C$54*Inputs!$C$58*Inputs!$C$45/1000*(1-Inputs!$C$46)*(1-Inputs!$C$51),0) -> 380.31808 | Q11: =IF(AND(2041>=Inputs!$C$53,2041<=2050),Inputs!$C$54*Inputs!$C$58*Inputs!$C$45/1000*(1-Inputs!$C$46)*(1-Inputs!$C$51),0) -> 380.31808 | R11: =IF(AND(2042>=Inputs!$C$53,2042<=2050),Inputs!$C$54*Inputs!$C$58*Inputs!$C$45/1000*(1-Inputs!$C$46)*(1-Inputs!$C$51),0) -> 380.31808 | S11: =IF(AND(2043>=Inputs!$C$53,2043<=2050),Inputs!$C$54*Inputs!$C$58*Inputs!$C$45/1000*(1-Inputs!$C$46)*(1-Inputs!$C$51),0) -> 380.31808 | T11: =IF(AND(2044>=Inputs!$C$53,2044<=2050),Inputs!$C$54*Inputs!$C$58*Inputs!$C$45/1000*(1-Inputs!$C$46)*(1-Inputs!$C$51),0) -> 380.31808 | U11: =IF(AND(2045>=Inputs!$C$53,2045<=2050),Inputs!$C$54*Inputs!$C$58*Inputs!$C$45/1000*(1-Inputs!$C$46)*(1-Inputs!$C$51),0) -> 380.31808 | V11: =IF(AND(2046>=Inputs!$C$53,2046<=2050),Inputs!$C$54*Inputs!$C$58*Inputs!$C$45/1000*(1-Inputs!$C$46)*(1-Inputs!$C$51),0) -> 380.31808 | W11: =IF(AND(2047>=Inputs!$C$53,2047<=2050),Inputs!$C$54*Inputs!$C$58*Inputs!$C$45/1000*(1-Inputs!$C$46)*(1-Inputs!$C$51),0) -> 380.31808 | X11: =IF(AND(2048>=Inputs!$C$53,2048<=2050),Inputs!$C$54*Inputs!$C$58*Inputs!$C$45/1000*(1-Inputs!$C$46)*(1-Inputs!$C$51),0) -> 380.31808 | Y11: =IF(AND(2049>=Inputs!$C$53,2049<=2050),Inputs!$C$54*Inputs!$C$58*Inputs!$C$45/1000*(1-Inputs!$C$46)*(1-Inputs!$C$51),0) -> 380.31808 | Z11: =IF(AND(2050>=Inputs!$C$53,2050<=2050),Inputs!$C$54*Inputs!$C$58*Inputs!$C$45/1000*(1-Inputs!$C$46)*(1-Inputs!$C$51),0) -> 380.31808 | AA11: =IF(AND(2051>=Inputs!$C$53,2051<=2050),Inputs!$C$54*Inputs!$C$58*Inputs!$C$45/1000*(1-Inputs!$C$46)*(1-Inputs!$C$51),0) -> 0 | AB11: =IF(AND(2052>=Inputs!$C$53,2052<=2050),Inputs!$C$54*Inputs!$C$58*Inputs!$C$45/1000*(1-Inputs!$C$46)*(1-Inputs!$C$51),0) -> 0 | AC11: =IF(AND(2053>=Inputs!$C$53,2053<=2050),Inputs!$C$54*Inputs!$C$58*Inputs!$C$45/1000*(1-Inputs!$C$46)*(1-Inputs!$C$51),0) -> 0 | AD11: =IF(AND(2054>=Inputs!$C$53,2054<=2050),Inputs!$C$54*Inputs!$C$58*Inputs!$C$45/1000*(1-Inputs!$C$46)*(1-Inputs!$C$51),0) -> 0 | AE11: =IF(AND(2055>=Inputs!$C$53,2055<=2050),Inputs!$C$54*Inputs!$C$58*Inputs!$C$45/1000*(1-Inputs!$C$46)*(1-Inputs!$C$51),0) -> 0 | AF11: =IF(AND(2056>=Inputs!$C$53,2056<=2050),Inputs!$C$54*Inputs!$C$58*Inputs!$C$45/1000*(1-Inputs!$C$46)*(1-Inputs!$C$51),0) -> 0 | AG11: =IF(AND(2057>=Inputs!$C$53,2057<=2050),Inputs!$C$54*Inputs!$C$58*Inputs!$C$45/1000*(1-Inputs!$C$46)*(1-Inputs!$C$51),0) -> 0 | AH11: =IF(AND(2058>=Inputs!$C$53,2058<=2050),Inputs!$C$54*Inputs!$C$58*Inputs!$C$45/1000*(1-Inputs!$C$46)*(1-Inputs!$C$51),0) -> 0 | AI11: =IF(AND(2059>=Inputs!$C$53,2059<=2050),Inputs!$C$54*Inputs!$C$58*Inputs!$C$45/1000*(1-Inputs!$C$46)*(1-Inputs!$C$51),0) -> 0 | AJ11: =IF(AND(2060>=Inputs!$C$53,2060<=2050),Inputs!$C$54*Inputs!$C$58*Inputs!$C$45/1000*(1-Inputs!$C$46)*(1-Inputs!$C$51),0) -> 0
A12: Cobre Panamá present value (unrisked) | B12: US$M | C12: =C11*C9 -> 0 | D12: =D11*D9 -> 0 | E12: =E11*E9 -> 336.64621 | F12: =F11*F9 -> 320.61544 | G12: =G11*G9 -> 305.34804 | H12: =H11*H9 -> 290.80765 | I12: =I11*I9 -> 276.95967 | J12: =J11*J9 -> 263.77111 | ... AJ12: =AJ11*AJ9 -> 0
A14: NAV summary
A15: Royalty and stream portfolio | B15: =SUM(C10:AJ10) -> 20274.274
A16: Cobre Panamá restart, unrisked | B16: =SUM(C12:AJ12) -> 4652.8387
A17: Cobre Panamá restart, risked | B17: =NAV!$B$16*Inputs!$C$55 -> 1628.4935 | C17: x probability
A18: Exploration and undeveloped optionality | B18: =Inputs!$C$56 -> 2000
A19: Cash, Dec 31, 2026E | B19: =Model!$F$30 -> 1686.1424
A20: Equity investments | B20: =Inputs!$C$44 -> 1215.1
A21: Net asset value | B21: =SUM(NAV!$B$15,NAV!$B$17,NAV!$B$18,NAV!$B$19,NAV!$B$20) -> 26804.01
A22: NAV per share (US$) | B22: =NAV!$B$21/Inputs!$C$57 -> 138.88088
A23: Risked Cobre Panamá value per share | B23: =NAV!$B$17/Inputs!$C$57 -> 8.4377904

Sheet Sensitivity
A1: Franco-Nevada Corporation — Sensitivity
A2: Every cell is a live formula on the model; nothing is pasted.
A4: Price target (USD, before rounding) vs. the two valuation multiples
A5: P/NAV down, P/CF 2027E across | B5: 20 | C5: 22.5 | D5: 25 | E5: 27.5 | F5: 30
A6: 1.5 | B6: =(Inputs!$C$37*$A6*Valuation!$B$23+(1-Inputs!$C$37)*B$5*Valuation!$B$26)/Inputs!$C$30 -> 194.13569 | C6: =(Inputs!$C$37*$A6*Valuation!$B$23+(1-Inputs!$C$37)*C$5*Valuation!$B$26)/Inputs!$C$30 -> 205.38257 | D6: =(Inputs!$C$37*$A6*Valuation!$B$23+(1-Inputs!$C$37)*D$5*Valuation!$B$26)/Inputs!$C$30 -> 216.62945 | E6: =(Inputs!$C$37*$A6*Valuation!$B$23+(1-Inputs!$C$37)*E$5*Valuation!$B$26)/Inputs!$C$30 -> 227.87633 | F6: =(Inputs!$C$37*$A6*Valuation!$B$23+(1-Inputs!$C$37)*F$5*Valuation!$B$26)/Inputs!$C$30 -> 239.12321
A7: 1.75 | B7: =(Inputs!$C$37*$A7*Valuation!$B$23+(1-Inputs!$C$37)*B$5*Valuation!$B$26)/Inputs!$C$30 -> 211.4958 | C7: =(Inputs!$C$37*$A7*Valuation!$B$23+(1-Inputs!$C$37)*C$5*Valuation!$B$26)/Inputs!$C$30 -> 222.74268 | D7: =(Inputs!$C$37*$A7*Valuation!$B$23+(1-Inputs!$C$37)*D$5*Valuation!$B$26)/Inputs!$C$30 -> 233.98956 | E7: =(Inputs!$C$37*$A7*Valuation!$B$23+(1-Inputs!$C$37)*E$5*Valuation!$B$26)/Inputs!$C$30 -> 245.23644 | F7: =(Inputs!$C$37*$A7*Valuation!$B$23+(1-Inputs!$C$37)*F$5*Valuation!$B$26)/Inputs!$C$30 -> 256.48332
A8: 2 | B8: =(Inputs!$C$37*$A8*Valuation!$B$23+(1-Inputs!$C$37)*B$5*Valuation!$B$26)/Inputs!$C$30 -> 228.85591 | C8: =(Inputs!$C$37*$A8*Valuation!$B$23+(1-Inputs!$C$37)*C$5*Valuation!$B$26)/Inputs!$C$30 -> 240.10279 | D8: =(Inputs!$C$37*$A8*Valuation!$B$23+(1-Inputs!$C$37)*D$5*Valuation!$B$26)/Inputs!$C$30 -> 251.34967 | E8: =(Inputs!$C$37*$A8*Valuation!$B$23+(1-Inputs!$C$37)*E$5*Valuation!$B$26)/Inputs!$C$30 -> 262.59655 | F8: =(Inputs!$C$37*$A8*Valuation!$B$23+(1-Inputs!$C$37)*F$5*Valuation!$B$26)/Inputs!$C$30 -> 273.84343
A9: 2.25 | B9: =(Inputs!$C$37*$A9*Valuation!$B$23+(1-Inputs!$C$37)*B$5*Valuation!$B$26)/Inputs!$C$30 -> 246.21602 | C9: =(Inputs!$C$37*$A9*Valuation!$B$23+(1-Inputs!$C$37)*C$5*Valuation!$B$26)/Inputs!$C$30 -> 257.4629 | D9: =(Inputs!$C$37*$A9*Valuation!$B$23+(1-Inputs!$C$37)*D$5*Valuation!$B$26)/Inputs!$C$30 -> 268.70978 | E9: =(Inputs!$C$37*$A9*Valuation!$B$23+(1-Inputs!$C$37)*E$5*Valuation!$B$26)/Inputs!$C$30 -> 279.95666 | F9: =(Inputs!$C$37*$A9*Valuation!$B$23+(1-Inputs!$C$37)*F$5*Valuation!$B$26)/Inputs!$C$30 -> 291.20354
A10: 2.5 | B10: =(Inputs!$C$37*$A10*Valuation!$B$23+(1-Inputs!$C$37)*B$5*Valuation!$B$26)/Inputs!$C$30 -> 263.57613 | C10: =(Inputs!$C$37*$A10*Valuation!$B$23+(1-Inputs!$C$37)*C$5*Valuation!$B$26)/Inputs!$C$30 -> 274.82301 | D10: =(Inputs!$C$37*$A10*Valuation!$B$23+(1-Inputs!$C$37)*D$5*Valuation!$B$26)/Inputs!$C$30 -> 286.06989 | E10: =(Inputs!$C$37*$A10*Valuation!$B$23+(1-Inputs!$C$37)*E$5*Valuation!$B$26)/Inputs!$C$30 -> 297.31677 | F10: =(Inputs!$C$37*$A10*Valuation!$B$23+(1-Inputs!$C$37)*F$5*Valuation!$B$26)/Inputs!$C$30 -> 308.56365
A13: DCF value per share vs. WACC (down) and terminal growth (across)
B14: 0 | C14: 0.01 | D14: 0.02 | E14: 0.03
A15: 0.06 | B15: =(Valuation!B44/(1+$A15)^1+Valuation!C44/(1+$A15)^2+Valuation!D44/(1+$A15)^3+Valuation!E44/(1+$A15)^4+Valuation!E44*(1+B$14)/($A15-B$14)/(1+$A15)^4-Valuation!$B$53+Valuation!$B$54)/Valuation!$B$7 -> 154.44171 | C15: =(Valuation!B44/(1+$A15)^1+Valuation!C44/(1+$A15)^2+Valuation!D44/(1+$A15)^3+Valuation!E44/(1+$A15)^4+Valuation!E44*(1+C$14)/($A15-C$14)/(1+$A15)^4-Valuation!$B$53+Valuation!$B$54)/Valuation!$B$7 -> 177.69963 | D15: =(Valuation!B44/(1+$A15)^1+Valuation!C44/(1+$A15)^2+Valuation!D44/(1+$A15)^3+Valuation!E44/(1+$A15)^4+Valuation!E44*(1+D$14)/($A15-D$14)/(1+$A15)^4-Valuation!$B$53+Valuation!$B$54)/Valuation!$B$7 -> 212.58652 | E15: =(Valuation!B44/(1+$A15)^1+Valuation!C44/(1+$A15)^2+Valuation!D44/(1+$A15)^3+Valuation!E44/(1+$A15)^4+Valuation!E44*(1+E$14)/($A15-E$14)/(1+$A15)^4-Valuation!$B$53+Valuation!$B$54)/Valuation!$B$7 -> 270.73133
A16: 0.07 | B16: =(Valuation!B44/(1+$A16)^1+Valuation!C44/(1+$A16)^2+Valuation!D44/(1+$A16)^3+Valuation!E44/(1+$A16)^4+Valuation!E44*(1+B$14)/($A16-B$14)/(1+$A16)^4-Valuation!$B$53+Valuation!$B$54)/Valuation!$B$7 -> 134.64495 | C16: =(Valuation!B44/(1+$A16)^1+Valuation!C44/(1+$A16)^2+Valuation!D44/(1+$A16)^3+Valuation!E44/(1+$A16)^4+Valuation!E44*(1+C$14)/($A16-C$14)/(1+$A16)^4-Valuation!$B$53+Valuation!$B$54)/Valuation!$B$7 -> 150.79631 | D16: =(Valuation!B44/(1+$A16)^1+Valuation!C44/(1+$A16)^2+Valuation!D44/(1+$A16)^3+Valuation!E44/(1+$A16)^4+Valuation!E44*(1+D$14)/($A16-D$14)/(1+$A16)^4-Valuation!$B$53+Valuation!$B$54)/Valuation!$B$7 -> 173.40822 | E16: =(Valuation!B44/(1+$A16)^1+Valuation!C44/(1+$A16)^2+Valuation!D44/(1+$A16)^3+Valuation!E44/(1+$A16)^4+Valuation!E44*(1+E$14)/($A16-E$14)/(1+$A16)^4-Valuation!$B$53+Valuation!$B$54)/Valuation!$B$7 -> 207.32608
A17: 0.08 | B17: =(Valuation!B44/(1+$A17)^1+Valuation!C44/(1+$A17)^2+Valuation!D44/(1+$A17)^3+Valuation!E44/(1+$A17)^4+Valuation!E44*(1+B$14)/($A17-B$14)/(1+$A17)^4-Valuation!$B$53+Valuation!$B$54)/Valuation!$B$7 -> 119.79496 | C17: =(Valuation!B44/(1+$A17)^1+Valuation!C44/(1+$A17)^2+Valuation!D44/(1+$A17)^3+Valuation!E44/(1+$A17)^4+Valuation!E44*(1+C$14)/($A17-C$14)/(1+$A17)^4-Valuation!$B$53+Valuation!$B$54)/Valuation!$B$7 -> 131.5751 | D17: =(Valuation!B44/(1+$A17)^1+Valuation!C44/(1+$A17)^2+Valuation!D44/(1+$A17)^3+Valuation!E44/(1+$A17)^4+Valuation!E44*(1+D$14)/($A17-D$14)/(1+$A17)^4-Valuation!$B$53+Valuation!$B$54)/Valuation!$B$7 -> 147.28195 | E17: =(Valuation!B44/(1+$A17)^1+Valuation!C44/(1+$A17)^2+Valuation!D44/(1+$A17)^3+Valuation!E44/(1+$A17)^4+Valuation!E44*(1+E$14)/($A17-E$14)/(1+$A17)^4-Valuation!$B$53+Valuation!$B$54)/Valuation!$B$7 -> 169.27155
A18: 0.09 | B18: =(Valuation!B44/(1+$A18)^1+Valuation!C44/(1+$A18)^2+Valuation!D44/(1+$A18)^3+Valuation!E44/(1+$A18)^4+Valuation!E44*(1+B$14)/($A18-B$14)/(1+$A18)^4-Valuation!$B$53+Valuation!$B$54)/Valuation!$B$7 -> 108.24288 | C18: =(Valuation!B44/(1+$A18)^1+Valuation!C44/(1+$A18)^2+Valuation!D44/(1+$A18)^3+Valuation!E44/(1+$A18)^4+Valuation!E44*(1+C$14)/($A18-C$14)/(1+$A18)^4-Valuation!$B$53+Valuation!$B$54)/Valuation!$B$7 -> 117.15535 | D18: =(Valuation!B44/(1+$A18)^1+Valuation!C44/(1+$A18)^2+Valuation!D44/(1+$A18)^3+Valuation!E44/(1+$A18)^4+Valuation!E44*(1+D$14)/($A18-D$14)/(1+$A18)^4-Valuation!$B$53+Valuation!$B$54)/Valuation!$B$7 -> 128.61423 | E18: =(Valuation!B44/(1+$A18)^1+Valuation!C44/(1+$A18)^2+Valuation!D44/(1+$A18)^3+Valuation!E44/(1+$A18)^4+Valuation!E44*(1+E$14)/($A18-E$14)/(1+$A18)^4-Valuation!$B$53+Valuation!$B$54)/Valuation!$B$7 -> 143.89274
A19: 0.1 | B19: =(Valuation!B44/(1+$A19)^1+Valuation!C44/(1+$A19)^2+Valuation!D44/(1+$A19)^3+Valuation!E44/(1+$A19)^4+Valuation!E44*(1+B$14)/($A19-B$14)/(1+$A19)^4-Valuation!$B$53+Valuation!$B$54)/Valuation!$B$7 -> 98.999417 | C19: =(Valuation!B44/(1+$A19)^1+Valuation!C44/(1+$A19)^2+Valuation!D44/(1+$A19)^3+Valuation!E44/(1+$A19)^4+Valuation!E44*(1+C$14)/($A19-C$14)/(1+$A19)^4-Valuation!$B$53+Valuation!$B$54)/Valuation!$B$7 -> 105.9367 | D19: =(Valuation!B44/(1+$A19)^1+Valuation!C44/(1+$A19)^2+Valuation!D44/(1+$A19)^3+Valuation!E44/(1+$A19)^4+Valuation!E44*(1+D$14)/($A19-D$14)/(1+$A19)^4-Valuation!$B$53+Valuation!$B$54)/Valuation!$B$7 -> 114.6083 | E19: =(Valuation!B44/(1+$A19)^1+Valuation!C44/(1+$A19)^2+Valuation!D44/(1+$A19)^3+Valuation!E44/(1+$A19)^4+Valuation!E44*(1+E$14)/($A19-E$14)/(1+$A19)^4-Valuation!$B$53+Valuation!$B$54)/Valuation!$B$7 -> 125.7575

Sheet Ratios
A1: Franco-Nevada Corporation — Financial analysis ratios
A2: CFA L2 Financial Statement Analysis: DuPont, cash conversion, leverage and payout. Formulas on the Model sheet.
A4: Ratio | B4: Unit | C4: 2025A | D4: H1-26A | E4: H2-26E | F4: 2026E | G4: 2027E | H4: 2028E | I4: 2029E | J4: 2030E | K4: Reading
A5: Adjusted EBITDA margin | C5: =IFERROR(Model!C13/Model!C10,"") -> 0.90854729 | F5: =IFERROR(Model!F13/Model!F10,"") -> 0.9073493 | G5: =IFERROR(Model!G13/Model!G10,"") -> 0.90250789 | H5: =IFERROR(Model!H13/Model!H10,"") -> 0.90079125 | I5: =IFERROR(Model!I13/Model!I10,"") -> 0.89953106 | J5: =IFERROR(Model!J13/Model!J10,"") -> 0.89879431
A6: Net margin (adjusted NI / revenue) | C6: =IFERROR(Model!C19/Model!C10,"") -> 0.58986175 | F6: =IFERROR(Model!F19/Model!F10,"") -> 0.62528564 | G6: =IFERROR(Model!G19/Model!G10,"") -> 0.58483479 | H6: =IFERROR(Model!H19/Model!H10,"") -> 0.57620715 | I6: =IFERROR(Model!I19/Model!I10,"") -> 0.56678314 | J6: =IFERROR(Model!J19/Model!J10,"") -> 0.56091228
A7: Equity turnover (revenue / average equity) | F7: =IFERROR(Model!F10/AVERAGE(Model!C32,Model!F32),"") -> 0.29098091 | G7: =IFERROR(Model!G10/AVERAGE(Model!F32,Model!G32),"") -> 0.24077168 | H7: =IFERROR(Model!H10/AVERAGE(Model!G32,Model!H32),"") -> 0.20833593 | I7: =IFERROR(Model!I10/AVERAGE(Model!H32,Model!I32),"") -> 0.18827932 | J7: =IFERROR(Model!J10/AVERAGE(Model!I32,Model!J32),"") -> 0.17637697
A8: Return on average equity | F8: =IFERROR(Model!F19/AVERAGE(Model!C32,Model!F32),"") -> 0.18194619 | G8: =IFERROR(Model!G19/AVERAGE(Model!F32,Model!G32),"") -> 0.14081166 | H8: =IFERROR(Model!H19/AVERAGE(Model!G32,Model!H32),"") -> 0.12004465 | I8: =IFERROR(Model!I19/AVERAGE(Model!H32,Model!I32),"") -> 0.10671354 | J8: =IFERROR(Model!J19/AVERAGE(Model!I32,Model!J32),"") -> 0.098932011 | K8: Two-step DuPont: net margin x equity turnover (no debt, so leverage ~1.0x)
A9: Cash conversion (operating cash flow / net income) | C9: =IFERROR(Model!C23/Model!C19,"") -> 1.3892299 | F9: =IFERROR(Model!F23/Model!F19,"") -> 1.277436 | G9: =IFERROR(Model!G23/Model!G19,"") -> 1.3406565 | H9: =IFERROR(Model!H23/Model!H19,"") -> 1.3624511 | I9: =IFERROR(Model!I23/Model!I19,"") -> 1.3873509 | J9: =IFERROR(Model!J23/Model!J19,"") -> 1.4029948
A10: Dividend payout (DPS / EPS) | C10: =IFERROR(Model!C26/Model!C21,"") -> 0.27241815 | F10: =IFERROR(Model!F26/Model!F21,"") -> 0.22781722 | G10: =IFERROR(Model!G26/Model!G21,"") -> 0.28608609 | H10: =IFERROR(Model!H26/Model!H21,"") -> 0.33297243 | I10: =IFERROR(Model!I26/Model!I21,"") -> 0.37570781 | J10: =IFERROR(Model!J26/Model!J21,"") -> 0.40875973
A11: Reinvestment rate ((dividends + acquisitions) / OCF) | G11: =IFERROR((Model!G27+Model!G28)/Model!G23,"") -> 0.50072951 | H11: =IFERROR((Model!H27+Model!H28)/Model!H23,"") -> 0.54753012 | I11: =IFERROR((Model!I27+Model!I28)/Model!I23,"") -> 0.58207906 | J11: =IFERROR((Model!J27+Model!J28)/Model!J23,"") -> 0.60325703

Sheet Comps
A1: Franco-Nevada Corporation — Peer comparison
A2: Senior royalty and streaming peers, H1-26 annualized (Royal Gold: Q2-26 annualized). Prices: FNV and RGLD Oct 26, WPM Oct 27, 2026.
A4: Company | B4: Ticker | C4: Price (US$) | D4: Mkt cap (US$B) | E4: P/E | F4: P/CF | G4: Net cash (US$B)
A5: Franco-Nevada | B5: FNV | C5: 230.76 | D5: 44.5 | E5: 27.5 | F5: 22.2 | G5: 1
A6: Wheaton Precious Metals | B6: WPM | C6: 124.59 | D6: 56.6 | E6: 25.1 | F6: 20 | G6: -1.9
A7: Royal Gold | B7: RGLD | C7: 234.11 | D7: 19.8 | E7: 22.9 | F7: 14.8 | G7: -0.3
A9: Source: Company Q2-26 filings; Northwall calculations

Sheet Checks
A1: Franco-Nevada Corporation — Model integrity checks
A2: Every check should read TRUE before anything is published.
A4: Check | B4: Model | C4: Expected | D4: Pass
A5: Price target equals the published target | B5: =Valuation!$B$34 -> 250 | C5: 250 | D5: =ABS(B5-C5)<=MAX(0.01,ABS(C5)*0.005) -> TRUE
A6: Rating equals the published rating | B6: =Valuation!$B$39 -> Hold | C6: Hold | D6: =B6=C6 -> TRUE
A7: NAV per share equals the published NAVPS | B7: =NAV!$B$22 -> 138.88088 | C7: 138.88 | D7: =ABS(B7-C7)<=MAX(0.01,ABS(C7)*0.005) -> TRUE
A8: 2026E adjusted EPS equals the published estimate | B8: =Model!$F$21 -> 7.7254915 | C8: 7.72 | D8: =ABS(B8-C8)<=MAX(0.01,ABS(C8)*0.005) -> TRUE
A9: 2027E CFPS equals the published estimate | B9: =Model!$G$24 -> 8.9975033 | C9: 9 | D9: =ABS(B9-C9)<=MAX(0.01,ABS(C9)*0.005) -> TRUE
A10: 2026E revenue = H1 actual + H2 estimate | B10: =Model!$F$10 -> 2384.542 | C10: =Model!$D$10+Model!$E$10 -> 2384.542 | D10: =ABS(B10-C10)<=MAX(0.01,ABS(C10)*0.005) -> TRUE
A12: All checks pass | D12: =AND(D5:D10) -> TRUE

Sheet Log
A1: Model change log
A2: Newest first. One row per change; never delete rows.
A4: Date | B4: Version | C4: Change | D4: Effect on target
A5: 2026-10-27 | B5: v2026Q2 | C5: Model built on house template from Q2-26 filings; ties to the published 2026-10-27 report | D5: Target US$250, Hold
