Workbook

Sheet Cover
A1: NORTHWALL RESEARCH
A2: Whitecap Resources Inc. (WCP)
A3: Canadian oil and gas producers · Analyst: Basel Al-Ghousein · Model version v2026Q2 · Built 2026-10-27
A5: Rating | B5: =Valuation!$B$44 -> Buy
A6: Price target (CAD) | B6: =Valuation!$B$39 -> 24
A7: Share price (CAD), TSX close Oct 23, 2026 (Stock Analysis) | B7: =Valuation!$B$5 -> 20.43
A8: Implied all-in return | B8: =Valuation!$B$43 -> 0.21045521
A9: Valuation method 1 | B9: =Valuation!$B$26 -> 23.21712
A10: Valuation method 2 | B10: =Valuation!$B$29 -> 24.004017
A11: DCF cross-check per share | B11: =Valuation!$B$60 -> 18.740689
A12: Cost of equity (CAPM) | B12: =Valuation!$B$16 -> 0.0842
A13: Market-implied growth | B13: =Valuation!$B$66 -> -0.094347293
A14: All integrity checks pass | B14: =IF(Checks!$D$12,"Yes","NO - see Checks") -> Yes
A16: Colour code
A17: Blue: typed input with a source (Inputs sheet only)
A18: Black: formula
A19: Green: link to another sheet
A20: Yellow fill: key assumption or output
A22: Sheets
A23: Inputs | B23: Every typed number, with its source
A24: Model | B24: Operations and financials, H1 actual + H2 estimate
A25: Valuation | B25: Target methods, CAPM/WACC, DCF, reverse DCF, residual income, justified P/E
A26: NAV | B26: Asset-life cash flows (resource names)
A27: Sensitivity | B27: Target and DCF grids
A28: Ratios | B28: DuPont, cash conversion, leverage, payout
A29: Comps | B29: Peer table
A30: Checks | B30: Integrity checks; all must be TRUE
A31: Log | B31: Every change, dated, with its reason

Sheet Inputs
A1: Whitecap Resources Inc. (WCP) — Inputs
A2: Every typed number in the model lives here, in blue, with its source. Change inputs here only.
A4: House price deck (from data/price_deck.yaml)
A5: Input | B5: Unit | C5: 2025A | D5: H1-26A | E5: H2-26E | F5: 2026E | G5: 2027E | H5: 2028E | I5: 2029E | J5: 2030E | K5: Source
A6: WTI, house deck | B6: US$/bbl | E6: 91.5 | G6: 80 | H6: 72 | I6: 70 | J6: 70 | K6: Northwall deck: Q3-26 ~88 and Q4-26 95 (avg 91.5); WTI ~US$101.8 on Oct 26, 2026 (DTN); normalizes to 70 as the Middle East premium fades
A8: Company drivers by period
A9: Input | B9: Unit | C9: 2025A | D9: H1-26A | E9: H2-26E | F9: 2026E | G9: 2027E | H9: 2028E | I9: 2029E | J9: 2030E | K9: Source
A10: Production | B10: kboe/d | D10: 390.155 | E10: 382.5 | G10: 397 | H10: 409 | I10: 421.3 | J10: 433.9 | K10: H1-26A: Q1 391,416 and Q2 388,894 boe/d (releases). H2-26E: Northwall, Q3 380k / Q4 385k vs 384-386k FY guidance. 2027E+: 3% growth (company base case)
A11: Days | B11: days | D11: 181 | E11: 184 | G11: 365 | H11: 365 | I11: 365 | J11: 365 | K11: Calendar
A12: Funds flow, reported | B12: C$M | D12: 2379.9 | K12: Q1-26 C$1,025.3M + Q2-26 C$1,354.6M (releases)
A13: Capital expenditures, reported | B13: C$M | D13: 1106.4 | K13: Q1-26 C$676.3M + Q2-26 C$430.1M
A14: Capital expenditures | B14: C$M | E14: =2100-1106.4 -> 993.6 | G14: 2100 | H14: 2100 | I14: 2100 | J14: 2100 | K14: High end of the C$2.0-2.1B 2026 budget (Q2-26 release); held flat
A15: Basic shares | B15: M | D15: 1215.7 | E15: 1215.7 | F15: 1215.7 | G15: 1215.7 | H15: 1215.7 | I15: 1215.7 | J15: 1215.7 | K15: Q2-26 release: 1,215.7M; no buybacks assumed
A16: Dividend per share | B16: C$ | D16: 0.36 | E16: 0.3648 | G16: 0.7296 | H16: 0.7296 | I16: 0.7296 | J16: 0.7296 | K16: C$0.0608 monthly (Oct 15, 2026 release)
A17: Net debt, reported | B17: C$M | D17: 2516.8 | K17: Q2-26 release
A19: Scalar inputs: market data, operating assumptions, valuation parameters
A20: Input | B20: Unit | C20: Value | K20: Source
A21: Share price | C21: 20.43 | K21: TSX close Oct 23, 2026 (Stock Analysis)
A22: Model currency per listing currency | C22: 1 | K22: Same currency
A23: Basic shares outstanding | B23: M | C23: 1215.7 | K23: Latest company filing
A24: Net debt at last balance sheet (negative = net cash) | B24: M | C24: 2516.8 | K24: Latest quarterly filing
A25: Equity beta | C25: 0.69 | K25: 5-year beta 0.69 (Stock Analysis)
A26: Pre-tax cost of debt | C26: 0.055 | K26: Northwall assumption: credit facility pricing
A27: Marginal tax rate | C27: 0.23 | K27: Statutory combined rate
A28: Gross debt | B28: M | C28: 2516.8 | K28: Latest quarterly filing
A29: Weight on valuation method 1 | C29: 0.5 | K29: Northwall method: equal weight
A30: Target multiple, method 1 | C30: 6.5 | K30: Northwall: modest premium to the current 6.0x for inventory, liquids and 0.5x leverage
A31: Target multiple, method 2 | C31: 0.08 | K31: Northwall target free funds flow yield
A32: Next-12-month dividend per share | C32: 0.7296 | K32: C$0.0608 monthly
A33: Target rounding increment | C33: 1 | K33: House style
A34: Buy threshold: expected 12-month total return | C34: 0.15 | K34: Northwall rating definitions
A35: Terminal growth for DCF cross-check (nominal) | C35: 0 | K35: Northwall: 0% for depleting oil assets, 2% for long-life gold portfolios
A36: Investments not captured in FCFF | B36: M | C36: 0 | K36: Balance sheet
A37: Funds flow per boe, Q2-26 actual | B37: C$/boe | C37: =1354.6/(388.894*91)*1000 -> 38.277048 | K37: Q2-26 funds flow / Q2-26 volume
A38: Funds flow sensitivity per US$1 WTI | B38: C$/boe | C38: 0.6 | K38: Northwall: ~52% oil and condensate weighting, royalties and FX
A39: WTI in the anchor quarter | B39: US$/bbl | C39: 92.79 | K39: Q2-26 average WTI (Greenfire Q2-26 release)
A40: After-tax interest added back for DACF | B40: C$M | C40: 110 | K40: Northwall estimate
A41: Risk-free rate (US 10-yr Treasury) | B41: % | C41: 0.0497 | K41: US 10-yr close 4.969% on Oct 26, 2026 (Mortgage News Daily)
A42: Equity risk premium | B42: % | C42: 0.05 | K42: Northwall assumption; within the 4-6% range of common historical and survey estimates (CFA L2 Return Concepts)

Sheet Model
A1: Whitecap Resources Inc. — Operating and financial model (CAD millions unless noted)
A2: H1-26A = reported six months; H2-26E = Northwall estimate; 2026E = H1 + H2. All cells are formulas.
A4: Line | B4: Unit | C4: 2025A | D4: H1-26A | E4: H2-26E | F4: 2026E | G4: 2027E | H4: 2028E | I4: 2029E | J4: 2030E | K4: Method
A5: Production and pricing
A6: Production | B6: kboe/d | D6: =Inputs!D10 -> 390.155 | E6: =Inputs!E10 -> 382.5 | F6: =(D6*D7+E6*E7)/F7 -> 386.29604 | G6: =Inputs!G10 -> 397 | H6: =Inputs!H10 -> 409 | I6: =Inputs!I10 -> 421.3 | J6: =Inputs!J10 -> 433.9
A7: Days in period | B7: days | D7: =Inputs!D11 -> 181 | E7: =Inputs!E11 -> 184 | F7: =D7+E7 -> 365 | G7: =Inputs!G11 -> 365 | H7: =Inputs!H11 -> 365 | I7: =Inputs!I11 -> 365 | J7: =Inputs!J11 -> 365
A8: Volume | B8: MMboe | D8: =D6*D7/1000 -> 70.618055 | E8: =E6*E7/1000 -> 70.38 | F8: =D8+E8 -> 140.99805 | G8: =G6*G7/1000 -> 144.905 | H8: =H6*H7/1000 -> 149.285 | I8: =I6*I7/1000 -> 153.7745 | J8: =J6*J7/1000 -> 158.3735
A9: WTI, house deck | B9: US$/bbl | E9: =Inputs!E6 -> 91.5 | G9: =Inputs!G6 -> 80 | H9: =Inputs!H6 -> 72 | I9: =Inputs!I6 -> 70 | J9: =Inputs!J6 -> 70
A10: Funds flow per boe | B10: C$/boe | D10: =D12/D8 -> 33.701013 | E10: =Inputs!$C$37+Inputs!$C$38*(E9-Inputs!$C$39) -> 37.503048 | F10: =F12/F8 -> 35.598821 | G10: =Inputs!$C$37+Inputs!$C$38*(G9-Inputs!$C$39) -> 30.603048 | H10: =Inputs!$C$37+Inputs!$C$38*(H9-Inputs!$C$39) -> 25.803048 | I10: =Inputs!$C$37+Inputs!$C$38*(I9-Inputs!$C$39) -> 24.603048 | J10: =Inputs!$C$37+Inputs!$C$38*(J9-Inputs!$C$39) -> 24.603048 | K10: Anchored to Q2-26 actual, flexed C$0.60/boe per US$1 WTI
A11: Cash flow
A12: Funds flow | B12: C$M | D12: =Inputs!D12 -> 2379.9 | E12: =E8*E10 -> 2639.4645 | F12: =D12+E12 -> 5019.3645 | G12: =G8*G10 -> 4434.5347 | H12: =H8*H10 -> 3852.008 | I12: =I8*I10 -> 3783.3214 | J12: =J8*J10 -> 3896.4708
A13: Basic shares | B13: M | D13: =Inputs!D15 -> 1215.7 | E13: =Inputs!E15 -> 1215.7 | F13: =Inputs!F15 -> 1215.7 | G13: =Inputs!G15 -> 1215.7 | H13: =Inputs!H15 -> 1215.7 | I13: =Inputs!I15 -> 1215.7 | J13: =Inputs!J15 -> 1215.7
A14: Funds flow per share | B14: C$ | D14: =D12/D13 -> 1.9576376 | E14: =E12/E13 -> 2.1711479 | F14: =F12/F13 -> 4.1287855 | G14: =G12/G13 -> 3.6477212 | H14: =H12/H13 -> 3.1685515 | I14: =I12/I13 -> 3.1120518 | J14: =J12/J13 -> 3.2051253
A15: Capital expenditures | B15: C$M | D15: =Inputs!D13 -> 1106.4 | E15: =Inputs!E14 -> 993.6 | F15: =D15+E15 -> 2100 | G15: =Inputs!G14 -> 2100 | H15: =Inputs!H14 -> 2100 | I15: =Inputs!I14 -> 2100 | J15: =Inputs!J14 -> 2100
A16: Free funds flow | B16: C$M | D16: =D12-D15 -> 1273.5 | E16: =E12-E15 -> 1645.8645 | F16: =D16+E16 -> 2919.3645 | G16: =G12-G15 -> 2334.5347 | H16: =H12-H15 -> 1752.008 | I16: =I12-I15 -> 1683.3214 | J16: =J12-J15 -> 1796.4708
A17: Free funds flow per share | B17: C$ | D17: =D16/D13 -> 1.0475446 | E17: =E16/E13 -> 1.353841 | F17: =F16/F13 -> 2.4013856 | G17: =G16/G13 -> 1.9203213 | H17: =H16/H13 -> 1.4411516 | I17: =I16/I13 -> 1.384652 | J17: =J16/J13 -> 1.4777254
A18: Debt-adjusted cash flow (FF + after-tax interest) | B18: C$M | F18: =F12+Inputs!$C$40 -> 5129.3645 | G18: =G12+Inputs!$C$40 -> 4544.5347 | H18: =H12+Inputs!$C$40 -> 3962.008 | I18: =I12+Inputs!$C$40 -> 3893.3214 | J18: =J12+Inputs!$C$40 -> 4006.4708
A19: Free cash flow to the firm | B19: C$M | G19: =G16+Inputs!$C$40 -> 2444.5347 | H19: =H16+Inputs!$C$40 -> 1862.008 | I19: =I16+Inputs!$C$40 -> 1793.3214 | J19: =J16+Inputs!$C$40 -> 1906.4708
A20: Dividend per share | B20: C$ | D20: =Inputs!D16 -> 0.36 | E20: =Inputs!E16 -> 0.3648 | F20: =D20+E20 -> 0.7248 | G20: =Inputs!G16 -> 0.7296 | H20: =Inputs!H16 -> 0.7296 | I20: =Inputs!I16 -> 0.7296 | J20: =Inputs!J16 -> 0.7296
A21: Dividends | B21: C$M | E21: =E20*E13 -> 443.48736 | G21: =G20*G13 -> 886.97472 | H21: =H20*H13 -> 886.97472 | I21: =I20*I13 -> 886.97472 | J21: =J20*J13 -> 886.97472
A22: Balance sheet
A23: Net debt, period end (negative = net cash) | B23: C$M | D23: =Inputs!D17 -> 2516.8 | E23: =D23-E16+E21 -> 1314.4228 | F23: =E23 -> 1314.4228 | G23: =F23-G16+G21 -> -133.1371 | H23: =G23-H16+H21 -> -998.17039 | I23: =H23-I16+I21 -> -1794.5171 | J23: =I23-J16+J21 -> -2704.0132 | K23: No buybacks assumed

Sheet Valuation
A1: Whitecap Resources Inc. — Valuation and price target
A2: Target methods first; CFA Level II cross-checks (DCF, reverse DCF, residual income, justified P/E) follow.
A4: Market data
A5: Share price (CAD) | B5: =Inputs!$C$21 -> 20.43 | C5: TSX close Oct 23, 2026 (Stock Analysis)
A6: Share price in model currency (CAD) | B6: =Inputs!$C$21*Inputs!$C$22 -> 20.43 | C6: Converted when the listing currency differs from the reporting currency
A7: Basic shares outstanding (M) | B7: =Inputs!$C$23 -> 1215.7
A8: Market capitalization (M) | B8: =Valuation!$B$6*Valuation!$B$7 -> 24836.751
A9: Net debt (cash) at last balance sheet (M) | B9: =Inputs!$C$24 -> 2516.8 | C9: Negative = net cash
A10: Enterprise value (M) | B10: =Valuation!$B$8+Valuation!$B$9 -> 27353.551 | C10: Market cap + net debt
A12: Required return on equity (CAPM) and WACC — CFA L2 Equity: Return Concepts; Corporate Issuers: Cost of Capital
A13: Risk-free rate (US 10-yr) | B13: =Inputs!$C$41 -> 0.0497 | C13: House deck
A14: Equity beta | B14: =Inputs!$C$25 -> 0.69 | C14: 5-year beta 0.69 (Stock Analysis)
A15: Equity risk premium | B15: =Inputs!$C$42 -> 0.05 | C15: House deck
A16: Cost of equity: rf + beta x ERP | B16: =Valuation!$B$13+Valuation!$B$14*Valuation!$B$15 -> 0.0842 | C16: CAPM
A17: Pre-tax cost of debt | B17: =Inputs!$C$26 -> 0.055 | C17: Northwall assumption: credit facility pricing
A18: Marginal tax rate | B18: =Inputs!$C$27 -> 0.23
A19: Debt weight: D / (D + E), market values | B19: =Inputs!$C$28/(Inputs!$C$28+Valuation!$B$8) -> 0.092009992 | C19: Gross debt at market cap
A20: WACC | B20: =Valuation!$B$16*(1-Valuation!$B$19)+Valuation!$B$17*(1-Valuation!$B$18)*Valuation!$B$19 -> 0.080349382 | C20: ke x E/V + kd x (1 - t) x D/V
A22: Target method 1: EV/DACF — method 2: free cash flow yield
A23: DACF, 2027E (C$M) | B23: =Model!$G$18 -> 4544.5347
A24: Target EV/DACF multiple | B24: =Inputs!$C$30 -> 6.5 | C24: Northwall: modest premium to the current 6.0x for inventory, liquids and 0.5x leverage
A25: Net debt, Dec 31, 2026E (C$M) | B25: =Model!$F$23 -> 1314.4228
A26: Method 1 value per share | B26: =(Valuation!$B$24*Valuation!$B$23-Valuation!$B$25)/Valuation!$B$7 -> 23.21712 | C26: (multiple x DACF - net debt) / shares
A27: Free funds flow, 2027E (C$M) | B27: =Model!$G$16 -> 2334.5347
A28: Target free funds flow yield | B28: =Inputs!$C$31 -> 0.08 | C28: Northwall target free funds flow yield
A29: Method 2 value per share | B29: =Valuation!$B$27/Valuation!$B$28/Valuation!$B$7 -> 24.004017 | C29: FFF / yield / shares
A30: Current EV / 2027E DACF | B30: =Valuation!$B$10/Valuation!$B$23 -> 6.0189993
A31: Current 2027E free funds flow yield | B31: =Valuation!$B$27/Valuation!$B$8 -> 0.093995171
A32: Dividend coverage
A33: WTI at which 2027E free funds flow covers the dividend (US$/bbl) | B33: =Inputs!$C$39+((Model!$G$20*Model!$G$13+Model!$G$15)/Model!$G$8-Inputs!$C$37)/Inputs!$C$38 -> 63.350472 | C33: Solves FF(WTI) - capital = dividends
A34: Price target and rating
A35: Weight on method 1 | B35: =Inputs!$C$29 -> 0.5
A36: Weight on method 2 | B36: =1-Inputs!$C$29 -> 0.5
A37: Blended value per share (CAD) | B37: =Valuation!$B$35*Valuation!$B$26+Valuation!$B$36*Valuation!$B$29 -> 23.610568
A38: Blended value per share (CAD) | B38: =Valuation!$B$37/Inputs!$C$22 -> 23.610568 | C38: Converted to listing currency
A39: 12-month price target (CAD), rounded | B39: =MROUND(Valuation!$B$38,Inputs!$C$33) -> 24 | C39: Rounded to the house increment
A40: Next-12-month dividend per share (listing currency) | B40: =Inputs!$C$32 -> 0.7296 | C40: C$0.0608 monthly
A41: Implied price return | B41: =Valuation!$B$39/Valuation!$B$5-1 -> 0.17474302
A42: Dividend yield | B42: =Valuation!$B$40/Valuation!$B$5 -> 0.035712188
A43: Implied all-in return | B43: =Valuation!$B$41+Valuation!$B$42 -> 0.21045521 | C43: Rating bands: Buy > 15%, Hold 0–15%, Sell < 0%
...

Sheet Sensitivity
A1: Whitecap Resources Inc. — Sensitivity
A2: Every cell is a live formula on the model; nothing is pasted.
A4: Price target (CAD, before rounding) vs. the two valuation multiples
A5: EV/DACF down, FFF yield across | B5: 0.07 | C5: 0.075 | D5: 0.08 | E5: 0.09 | F5: 0.1
A6: 5.5 | B6: =(Inputs!$C$29*($A6*Valuation!$B$23-Valuation!$B$25)/Valuation!$B$7+(1-Inputs!$C$29)*Valuation!$B$27/B$5/Valuation!$B$7)/Inputs!$C$22 -> 23.456039 | C6: =(Inputs!$C$29*($A6*Valuation!$B$23-Valuation!$B$25)/Valuation!$B$7+(1-Inputs!$C$29)*Valuation!$B$27/C$5/Valuation!$B$7)/Inputs!$C$22 -> 22.5416 | D6: =(Inputs!$C$29*($A6*Valuation!$B$23-Valuation!$B$25)/Valuation!$B$7+(1-Inputs!$C$29)*Valuation!$B$27/D$5/Valuation!$B$7)/Inputs!$C$22 -> 21.741466 | E6: =(Inputs!$C$29*($A6*Valuation!$B$23-Valuation!$B$25)/Valuation!$B$7+(1-Inputs!$C$29)*Valuation!$B$27/E$5/Valuation!$B$7)/Inputs!$C$22 -> 20.40791 | F6: =(Inputs!$C$29*($A6*Valuation!$B$23-Valuation!$B$25)/Valuation!$B$7+(1-Inputs!$C$29)*Valuation!$B$27/F$5/Valuation!$B$7)/Inputs!$C$22 -> 19.341065
A7: 6 | B7: =(Inputs!$C$29*($A7*Valuation!$B$23-Valuation!$B$25)/Valuation!$B$7+(1-Inputs!$C$29)*Valuation!$B$27/B$5/Valuation!$B$7)/Inputs!$C$22 -> 24.39059 | C7: =(Inputs!$C$29*($A7*Valuation!$B$23-Valuation!$B$25)/Valuation!$B$7+(1-Inputs!$C$29)*Valuation!$B$27/C$5/Valuation!$B$7)/Inputs!$C$22 -> 23.476151 | D7: =(Inputs!$C$29*($A7*Valuation!$B$23-Valuation!$B$25)/Valuation!$B$7+(1-Inputs!$C$29)*Valuation!$B$27/D$5/Valuation!$B$7)/Inputs!$C$22 -> 22.676017 | E7: =(Inputs!$C$29*($A7*Valuation!$B$23-Valuation!$B$25)/Valuation!$B$7+(1-Inputs!$C$29)*Valuation!$B$27/E$5/Valuation!$B$7)/Inputs!$C$22 -> 21.342461 | F7: =(Inputs!$C$29*($A7*Valuation!$B$23-Valuation!$B$25)/Valuation!$B$7+(1-Inputs!$C$29)*Valuation!$B$27/F$5/Valuation!$B$7)/Inputs!$C$22 -> 20.275616
A8: 6.5 | B8: =(Inputs!$C$29*($A8*Valuation!$B$23-Valuation!$B$25)/Valuation!$B$7+(1-Inputs!$C$29)*Valuation!$B$27/B$5/Valuation!$B$7)/Inputs!$C$22 -> 25.325141 | C8: =(Inputs!$C$29*($A8*Valuation!$B$23-Valuation!$B$25)/Valuation!$B$7+(1-Inputs!$C$29)*Valuation!$B$27/C$5/Valuation!$B$7)/Inputs!$C$22 -> 24.410702 | D8: =(Inputs!$C$29*($A8*Valuation!$B$23-Valuation!$B$25)/Valuation!$B$7+(1-Inputs!$C$29)*Valuation!$B$27/D$5/Valuation!$B$7)/Inputs!$C$22 -> 23.610568 | E8: =(Inputs!$C$29*($A8*Valuation!$B$23-Valuation!$B$25)/Valuation!$B$7+(1-Inputs!$C$29)*Valuation!$B$27/E$5/Valuation!$B$7)/Inputs!$C$22 -> 22.277012 | F8: =(Inputs!$C$29*($A8*Valuation!$B$23-Valuation!$B$25)/Valuation!$B$7+(1-Inputs!$C$29)*Valuation!$B$27/F$5/Valuation!$B$7)/Inputs!$C$22 -> 21.210167
A9: 7 | B9: =(Inputs!$C$29*($A9*Valuation!$B$23-Valuation!$B$25)/Valuation!$B$7+(1-Inputs!$C$29)*Valuation!$B$27/B$5/Valuation!$B$7)/Inputs!$C$22 -> 26.259692 | C9: =(Inputs!$C$29*($A9*Valuation!$B$23-Valuation!$B$25)/Valuation!$B$7+(1-Inputs!$C$29)*Valuation!$B$27/C$5/Valuation!$B$7)/Inputs!$C$22 -> 25.345253 | D9: =(Inputs!$C$29*($A9*Valuation!$B$23-Valuation!$B$25)/Valuation!$B$7+(1-Inputs!$C$29)*Valuation!$B$27/D$5/Valuation!$B$7)/Inputs!$C$22 -> 24.545119 | E9: =(Inputs!$C$29*($A9*Valuation!$B$23-Valuation!$B$25)/Valuation!$B$7+(1-Inputs!$C$29)*Valuation!$B$27/E$5/Valuation!$B$7)/Inputs!$C$22 -> 23.211563 | F9: =(Inputs!$C$29*($A9*Valuation!$B$23-Valuation!$B$25)/Valuation!$B$7+(1-Inputs!$C$29)*Valuation!$B$27/F$5/Valuation!$B$7)/Inputs!$C$22 -> 22.144718
A10: 7.5 | B10: =(Inputs!$C$29*($A10*Valuation!$B$23-Valuation!$B$25)/Valuation!$B$7+(1-Inputs!$C$29)*Valuation!$B$27/B$5/Valuation!$B$7)/Inputs!$C$22 -> 27.194243 | C10: =(Inputs!$C$29*($A10*Valuation!$B$23-Valuation!$B$25)/Valuation!$B$7+(1-Inputs!$C$29)*Valuation!$B$27/C$5/Valuation!$B$7)/Inputs!$C$22 -> 26.279804 | D10: =(Inputs!$C$29*($A10*Valuation!$B$23-Valuation!$B$25)/Valuation!$B$7+(1-Inputs!$C$29)*Valuation!$B$27/D$5/Valuation!$B$7)/Inputs!$C$22 -> 25.47967 | E10: =(Inputs!$C$29*($A10*Valuation!$B$23-Valuation!$B$25)/Valuation!$B$7+(1-Inputs!$C$29)*Valuation!$B$27/E$5/Valuation!$B$7)/Inputs!$C$22 -> 24.146114 | F10: =(Inputs!$C$29*($A10*Valuation!$B$23-Valuation!$B$25)/Valuation!$B$7+(1-Inputs!$C$29)*Valuation!$B$27/F$5/Valuation!$B$7)/Inputs!$C$22 -> 23.079269
A13: DCF value per share vs. WACC (down) and terminal growth (across)
B14: 0 | C14: 0.01 | D14: 0.02 | E14: 0.03
A15: 0.06 | B15: =(Valuation!B49/(1+$A15)^1+Valuation!C49/(1+$A15)^2+Valuation!D49/(1+$A15)^3+Valuation!E49/(1+$A15)^4+Valuation!E49*(1+B$14)/($A15-B$14)/(1+$A15)^4-Valuation!$B$58+Valuation!$B$59)/Valuation!$B$7 -> 25.362445 | C15: =(Valuation!B49/(1+$A15)^1+Valuation!C49/(1+$A15)^2+Valuation!D49/(1+$A15)^3+Valuation!E49/(1+$A15)^4+Valuation!E49*(1+C$14)/($A15-C$14)/(1+$A15)^4-Valuation!$B$58+Valuation!$B$59)/Valuation!$B$7 -> 29.751438 | D15: =(Valuation!B49/(1+$A15)^1+Valuation!C49/(1+$A15)^2+Valuation!D49/(1+$A15)^3+Valuation!E49/(1+$A15)^4+Valuation!E49*(1+D$14)/($A15-D$14)/(1+$A15)^4-Valuation!$B$58+Valuation!$B$59)/Valuation!$B$7 -> 36.334927 | E15: =(Valuation!B49/(1+$A15)^1+Valuation!C49/(1+$A15)^2+Valuation!D49/(1+$A15)^3+Valuation!E49/(1+$A15)^4+Valuation!E49*(1+E$14)/($A15-E$14)/(1+$A15)^4-Valuation!$B$58+Valuation!$B$59)/Valuation!$B$7 -> 47.30741
A16: 0.07 | B16: =(Valuation!B49/(1+$A16)^1+Valuation!C49/(1+$A16)^2+Valuation!D49/(1+$A16)^3+Valuation!E49/(1+$A16)^4+Valuation!E49*(1+B$14)/($A16-B$14)/(1+$A16)^4-Valuation!$B$58+Valuation!$B$59)/Valuation!$B$7 -> 21.627489 | C16: =(Valuation!B49/(1+$A16)^1+Valuation!C49/(1+$A16)^2+Valuation!D49/(1+$A16)^3+Valuation!E49/(1+$A16)^4+Valuation!E49*(1+C$14)/($A16-C$14)/(1+$A16)^4-Valuation!$B$58+Valuation!$B$59)/Valuation!$B$7 -> 24.675406 | D16: =(Valuation!B49/(1+$A16)^1+Valuation!C49/(1+$A16)^2+Valuation!D49/(1+$A16)^3+Valuation!E49/(1+$A16)^4+Valuation!E49*(1+D$14)/($A16-D$14)/(1+$A16)^4-Valuation!$B$58+Valuation!$B$59)/Valuation!$B$7 -> 28.94249 | E16: =(Valuation!B49/(1+$A16)^1+Valuation!C49/(1+$A16)^2+Valuation!D49/(1+$A16)^3+Valuation!E49/(1+$A16)^4+Valuation!E49*(1+E$14)/($A16-E$14)/(1+$A16)^4-Valuation!$B$58+Valuation!$B$59)/Valuation!$B$7 -> 35.343115
A17: 0.08 | B17: =(Valuation!B49/(1+$A17)^1+Valuation!C49/(1+$A17)^2+Valuation!D49/(1+$A17)^3+Valuation!E49/(1+$A17)^4+Valuation!E49*(1+B$14)/($A17-B$14)/(1+$A17)^4-Valuation!$B$58+Valuation!$B$59)/Valuation!$B$7 -> 18.825967 | C17: =(Valuation!B49/(1+$A17)^1+Valuation!C49/(1+$A17)^2+Valuation!D49/(1+$A17)^3+Valuation!E49/(1+$A17)^4+Valuation!E49*(1+C$14)/($A17-C$14)/(1+$A17)^4-Valuation!$B$58+Valuation!$B$59)/Valuation!$B$7 -> 21.048993 | D17: =(Valuation!B49/(1+$A17)^1+Valuation!C49/(1+$A17)^2+Valuation!D49/(1+$A17)^3+Valuation!E49/(1+$A17)^4+Valuation!E49*(1+D$14)/($A17-D$14)/(1+$A17)^4-Valuation!$B$58+Valuation!$B$59)/Valuation!$B$7 -> 24.013027 | E17: =(Valuation!B49/(1+$A17)^1+Valuation!C49/(1+$A17)^2+Valuation!D49/(1+$A17)^3+Valuation!E49/(1+$A17)^4+Valuation!E49*(1+E$14)/($A17-E$14)/(1+$A17)^4-Valuation!$B$58+Valuation!$B$59)/Valuation!$B$7 -> 28.162674
A18: 0.09 | B18: =(Valuation!B49/(1+$A18)^1+Valuation!C49/(1+$A18)^2+Valuation!D49/(1+$A18)^3+Valuation!E49/(1+$A18)^4+Valuation!E49*(1+B$14)/($A18-B$14)/(1+$A18)^4-Valuation!$B$58+Valuation!$B$59)/Valuation!$B$7 -> 16.646728 | C18: =(Valuation!B49/(1+$A18)^1+Valuation!C49/(1+$A18)^2+Valuation!D49/(1+$A18)^3+Valuation!E49/(1+$A18)^4+Valuation!E49*(1+C$14)/($A18-C$14)/(1+$A18)^4-Valuation!$B$58+Valuation!$B$59)/Valuation!$B$7 -> 18.328595 | D18: =(Valuation!B49/(1+$A18)^1+Valuation!C49/(1+$A18)^2+Valuation!D49/(1+$A18)^3+Valuation!E49/(1+$A18)^4+Valuation!E49*(1+D$14)/($A18-D$14)/(1+$A18)^4-Valuation!$B$58+Valuation!$B$59)/Valuation!$B$7 -> 20.490996 | E18: =(Valuation!B49/(1+$A18)^1+Valuation!C49/(1+$A18)^2+Valuation!D49/(1+$A18)^3+Valuation!E49/(1+$A18)^4+Valuation!E49*(1+E$14)/($A18-E$14)/(1+$A18)^4-Valuation!$B$58+Valuation!$B$59)/Valuation!$B$7 -> 23.374198
A19: 0.1 | B19: =(Valuation!B49/(1+$A19)^1+Valuation!C49/(1+$A19)^2+Valuation!D49/(1+$A19)^3+Valuation!E49/(1+$A19)^4+Valuation!E49*(1+B$14)/($A19-B$14)/(1+$A19)^4-Valuation!$B$58+Valuation!$B$59)/Valuation!$B$7 -> 14.903082 | C19: =(Valuation!B49/(1+$A19)^1+Valuation!C49/(1+$A19)^2+Valuation!D49/(1+$A19)^3+Valuation!E49/(1+$A19)^4+Valuation!E49*(1+C$14)/($A19-C$14)/(1+$A19)^4-Valuation!$B$58+Valuation!$B$59)/Valuation!$B$7 -> 16.212214 | D19: =(Valuation!B49/(1+$A19)^1+Valuation!C49/(1+$A19)^2+Valuation!D49/(1+$A19)^3+Valuation!E49/(1+$A19)^4+Valuation!E49*(1+D$14)/($A19-D$14)/(1+$A19)^4-Valuation!$B$58+Valuation!$B$59)/Valuation!$B$7 -> 17.848628 | E19: =(Valuation!B49/(1+$A19)^1+Valuation!C49/(1+$A19)^2+Valuation!D49/(1+$A19)^3+Valuation!E49/(1+$A19)^4+Valuation!E49*(1+E$14)/($A19-E$14)/(1+$A19)^4-Valuation!$B$58+Valuation!$B$59)/Valuation!$B$7 -> 19.952589

Sheet Ratios
A1: Whitecap Resources Inc. — Financial analysis ratios
A2: CFA L2 Financial Statement Analysis: DuPont, cash conversion, leverage and payout. Formulas on the Model sheet.
A4: Ratio | B4: Unit | C4: 2025A | D4: H1-26A | E4: H2-26E | F4: 2026E | G4: 2027E | H4: 2028E | I4: 2029E | J4: 2030E | K4: Reading
A5: Reinvestment rate (capital / funds flow) | D5: =IFERROR(Model!D15/Model!D12,"") -> 0.46489348 | E5: =IFERROR(Model!E15/Model!E12,"") -> 0.37643999 | F5: =IFERROR(Model!F15/Model!F12,"") -> 0.41837966 | G5: =IFERROR(Model!G15/Model!G12,"") -> 0.47355589 | H5: =IFERROR(Model!H15/Model!H12,"") -> 0.54517021 | I5: =IFERROR(Model!I15/Model!I12,"") -> 0.55506783 | J5: =IFERROR(Model!J15/Model!J12,"") -> 0.53894924
A6: Dividend payout of free funds flow | F6: =IFERROR(Model!F20*Model!F13/Model!F16,"") -> 0.30182574 | G6: =IFERROR(Model!G20*Model!G13/Model!G16,"") -> 0.37993641 | H6: =IFERROR(Model!H20*Model!H13/Model!H16,"") -> 0.50626179 | I6: =IFERROR(Model!I20*Model!I13/Model!I16,"") -> 0.52691941 | J6: =IFERROR(Model!J20*Model!J13/Model!J16,"") -> 0.49373177
A7: Net debt / funds flow | F7: =IFERROR(Model!F23/Model!F12,"") -> 0.26187037 | G7: =IFERROR(Model!G23/Model!G12,"") -> -0.030022789 | H7: =IFERROR(Model!H23/Model!H12,"") -> -0.25912988 | I7: =IFERROR(Model!I23/Model!I12,"") -> -0.47432319 | J7: =IFERROR(Model!J23/Model!J12,"") -> -0.69396469
A8: Funds flow per share growth | G8: =IFERROR(Model!G14/Model!F14-1,"") -> -0.11651472 | H8: =IFERROR(Model!H14/Model!G14-1,"") -> -0.13136139 | I8: =IFERROR(Model!I14/Model!H14-1,"") -> -0.017831379 | J8: =IFERROR(Model!J14/Model!I14-1,"") -> 0.029907429 | K8: Mostly price-driven: the deck falls from US$91.5 to US$70

Sheet Comps
A1: Whitecap Resources Inc. — Peer comparison
A2: Canadian producers, Q2-26 annualized. Prices: WCP Oct 23, TOU Oct 22, SCR Oct 15, 2026.
A4: Company | B4: Ticker | C4: Price (C$) | D4: Mkt cap (C$B) | E4: EV/CF | F4: FCF yield | G4: Div yield | H4: ND/CF
A5: Whitecap | B5: WCP | C5: 20.43 | D5: 24.8 | E5: 5.0x | F5: 14.9% | G5: 3.6% | H5: 0.5x
A6: Tourmaline | B6: TOU | C6: 65.86 | D6: 25.7 | E6: 8.6x | F6: 3.0% | G6: 3.0% | H6: 0.5x
A7: Strathcona | B7: SCR | C7: 41.73 | D7: 8.9 | E7: 5.0x | F7: 13.3% | G7: 2.9% | H7: 0.9x
A9: Source: Company Q2-26 filings; Northwall calculations

Sheet Checks
A1: Whitecap Resources Inc. — Model integrity checks
A2: Every check should read TRUE before anything is published.
A4: Check | B4: Model | C4: Expected | D4: Pass
A5: Price target equals the published target | B5: =Valuation!$B$39 -> 24 | C5: 24 | D5: =ABS(B5-C5)<=MAX(0.01,ABS(C5)*0.005) -> TRUE
A6: Rating equals the published rating | B6: =Valuation!$B$44 -> Buy | C6: Buy | D6: =B6=C6 -> TRUE
A7: 2027E funds flow per share equals the published estimate | B7: =Model!$G$14 -> 3.6477212 | C7: 3.65 | D7: =ABS(B7-C7)<=MAX(0.01,ABS(C7)*0.005) -> TRUE
A8: 2027E free funds flow equals the published estimate | B8: =Model!$G$16 -> 2334.5347 | C8: 2335 | D8: =ABS(B8-C8)<=MAX(0.01,ABS(C8)*0.005) -> TRUE
A9: Net debt at Dec 31, 2026E equals the published estimate | B9: =Model!$F$23 -> 1314.4228 | C9: 1313 | D9: =ABS(B9-C9)<=MAX(0.01,ABS(C9)*0.005) -> TRUE
A10: Dividend breakeven WTI equals the published ~US$63 | B10: =Valuation!$B$33 -> 63.350472 | C10: 63.4 | D10: =ABS(B10-C10)<=MAX(0.01,ABS(C10)*0.005) -> TRUE
A12: All checks pass | D12: =AND(D5:D10) -> TRUE

Sheet Log
A1: Model change log
A2: Newest first. One row per change; never delete rows.
A4: Date | B4: Version | C4: Change | D4: Effect on target
A5: 2026-10-27 | B5: v2026Q2 | C5: Model built on house template from Q2-26 filings; ties to the published 2026-10-27 report | D5: Target C$24, Buy
