Workbook

Sheet Cover
A1: NORTHWALL RESEARCH
A2: Greenfire Resources Ltd. (GFR)
A3: Canadian oil sands · Analyst: Basel Al-Ghousein · Model version v2026Q2 · Built 2026-10-27
A5: Rating | B5: =Valuation!$B$43 -> Buy
A6: Price target (USD) | B6: =Valuation!$B$38 -> 8.25
A7: Share price (USD), NYSE close Oct 26, 2026 (StockScan) | B7: =Valuation!$B$5 -> 7
A8: Implied all-in return | B8: =Valuation!$B$42 -> 0.17857143
A9: Valuation method 1 | B9: =Valuation!$B$28 -> 12.233777
A10: Valuation method 2 | B10: =Valuation!$B$31 -> 11.217138
A11: DCF cross-check per share | B11: =Valuation!$B$59 -> 10.938171
A12: Cost of equity (CAPM) | B12: =Valuation!$B$16 -> 0.1147
A13: Market-implied growth | B13: =Valuation!$B$65 -> -0.13974991
A14: All integrity checks pass | B14: =IF(Checks!$D$12,"Yes","NO - see Checks") -> Yes
A16: Colour code
A17: Blue: typed input with a source (Inputs sheet only)
A18: Black: formula
A19: Green: link to another sheet
A20: Yellow fill: key assumption or output
A22: Sheets
A23: Inputs | B23: Every typed number, with its source
A24: Model | B24: Operations and financials, H1 actual + H2 estimate
A25: Valuation | B25: Target methods, CAPM/WACC, DCF, reverse DCF, residual income, justified P/E
A26: NAV | B26: Asset-life cash flows (resource names)
A27: Sensitivity | B27: Target and DCF grids
A28: Ratios | B28: DuPont, cash conversion, leverage, payout
A29: Comps | B29: Peer table
A30: Checks | B30: Integrity checks; all must be TRUE
A31: Log | B31: Every change, dated, with its reason

Sheet Inputs
A1: Greenfire Resources Ltd. (GFR) — Inputs
A2: Every typed number in the model lives here, in blue, with its source. Change inputs here only.
A4: House price deck (from data/price_deck.yaml)
A5: Input | B5: Unit | C5: 2025A | D5: H1-26A | E5: H2-26E | F5: 2026E | G5: 2027E | H5: 2028E | I5: 2029E | J5: 2030E | K5: Source
A6: WTI, house deck | B6: US$/bbl | E6: 91.5 | G6: 80 | H6: 72 | I6: 70 | J6: 70 | K6: Northwall deck: Q3-26 ~88 and Q4-26 95 (avg 91.5); WTI ~US$101.8 on Oct 26, 2026 (DTN); normalizes to 70 as the Middle East premium fades
A8: Company drivers by period
A9: Input | B9: Unit | C9: 2025A | D9: H1-26A | E9: H2-26E | F9: 2026E | G9: 2027E | H9: 2028E | I9: 2029E | J9: 2030E | K9: Source
A10: Bitumen production | B10: kbbl/d | C10: 16.169 | F10: 22.5 | G10: 40 | H10: 46 | I10: 50 | J10: 54 | K10: 2025A: YE2025 release. 2026E: Northwall, inside 21.5-23.5k guidance incl. Connacher from Aug 5. 2027E+: Northwall; Pads 7, 5SE, 8 and Great Divide infill toward the ~65k long-term plan
A11: Adjusted funds flow, reported | B11: C$M | C11: 143.5 | K11: YE2025 release
A12: Capital expenditures, reported | B12: C$M | C12: 111.8 | K12: YE2025 release
A13: Adjusted free cash flow, reported | B13: C$M | C13: 31.7 | K13: YE2025 release
A14: Interest | B14: C$M | G14: 45 | H14: 38 | I14: 32 | J14: 26 | K14: Northwall: ~C$570M drawn at ~7.5-8%, falling with debt
A15: Capital expenditures | B15: C$M | G15: 330 | H15: 300 | I15: 300 | J15: 300 | K15: Northwall: Connacher sustaining ~C$75M (company) + Hangingstone pads
A16: Basic shares | B16: M | F16: 240.4 | G16: 240.4 | H16: 240.4 | I16: 240.4 | J16: 240.4 | K16: Rights offering closing (Sep 16, 2026): 240,413,692
A17: Net debt, Dec 31, 2026E | B17: C$M | F17: 530 | K17: Northwall: ~C$570M drawn (rights offering release) less ~C$40M Q4 free cash flow
A19: Scalar inputs: market data, operating assumptions, valuation parameters
A20: Input | B20: Unit | C20: Value | K20: Source
A21: Share price | C21: 7 | K21: NYSE close Oct 26, 2026 (StockScan)
A22: Model currency per listing currency | C22: 1.402 | K22: USD/CAD 1.402 on Oct 27, 2026 (fxfeed.io)
A23: Basic shares outstanding | B23: M | C23: 240.4 | K23: Latest company filing
A24: Net debt at last balance sheet (negative = net cash) | B24: M | C24: 570 | K24: Latest quarterly filing
A25: Equity beta | C25: 1.3 | K25: Northwall assumption pending sourcing
A26: Pre-tax cost of debt | C26: 0.08 | K26: Northwall assumption: credit facility pricing
A27: Marginal tax rate | C27: 0.23 | K27: Statutory combined rate
A28: Gross debt | B28: M | C28: 570 | K28: Latest quarterly filing
A29: Weight on valuation method 1 | C29: 0.5 | K29: Northwall method: equal weight
A30: Target multiple, method 1 | C30: 0.85 | K30: Northwall: discount for a 72% controlling shareholder and thin float
A31: Target multiple, method 2 | C31: 5 | K31: Northwall: in line with Strathcona at ~5.0x annualized EV/CF
A32: Next-12-month dividend per share | C32: 0 | K32: No dividend
A33: Target rounding increment | C33: 0.25 | K33: House style
A34: Buy threshold: expected 12-month total return | C34: 0.15 | K34: Northwall rating definitions
A35: Terminal growth for DCF cross-check (nominal) | C35: 0 | K35: Northwall: 0% for depleting oil assets, 2% for long-life gold portfolios
A36: Investments not captured in FCFF | B36: M | C36: 0 | K36: Balance sheet
A37: EBITDA per bbl at US$70 WTI | B37: C$/bbl | C37: 32.5 | K37: Company: ~1.2x debt / 2027E EBITDA at US$70 with ~C$570M drawn -> ~C$475M / 40k bbl/d
A38: EBITDA sensitivity per US$1 WTI | B38: C$/bbl | C38: 1.17 | K38: Northwall: 1.38 USD/CAD x ~85% after royalties
A39: WTI at the anchor | B39: US$/bbl | C39: 70 | K39: Company guidance basis
A40: Greenfire 2P after-tax PV10, YE2025 | B40: C$M | C40: 1990 | K40: YE2025 reserves release
A41: Connacher 2P value | B41: C$M | C41: 2000 | K41: Northwall estimate: 2P NAV10 before tax C$2,124M (acquisition release); no cash tax before 2030
A42: Current production | B42: bbl/d | C42: 34000 | K42: Company, pro forma Connacher (Q2-26 release)
A43: Risk-free rate (US 10-yr Treasury) | B43: % | C43: 0.0497 | K43: US 10-yr close 4.969% on Oct 26, 2026 (Mortgage News Daily)
...

Sheet Model
A1: Greenfire Resources Ltd. — Operating and financial model (CAD millions unless noted)
A2: H1-26A = reported six months; H2-26E = Northwall estimate; 2026E = H1 + H2. All cells are formulas.
A4: Line | B4: Unit | C4: 2025A | D4: H1-26A | E4: H2-26E | F4: 2026E | G4: 2027E | H4: 2028E | I4: 2029E | J4: 2030E | K4: Method
A5: Production and pricing
A6: Bitumen production | B6: kbbl/d | C6: =Inputs!C10 -> 16.169 | F6: =Inputs!F10 -> 22.5 | G6: =Inputs!G10 -> 40 | H6: =Inputs!H10 -> 46 | I6: =Inputs!I10 -> 50 | J6: =Inputs!J10 -> 54
A7: WTI, house deck | B7: US$/bbl | G7: =Inputs!G6 -> 80 | H7: =Inputs!H6 -> 72 | I7: =Inputs!I6 -> 70 | J7: =Inputs!J6 -> 70
A8: Adjusted EBITDA per barrel | B8: C$/bbl | G8: =Inputs!$C$37+Inputs!$C$38*(G7-Inputs!$C$39) -> 44.2 | H8: =Inputs!$C$37+Inputs!$C$38*(H7-Inputs!$C$39) -> 34.84 | I8: =Inputs!$C$37+Inputs!$C$38*(I7-Inputs!$C$39) -> 32.5 | J8: =Inputs!$C$37+Inputs!$C$38*(J7-Inputs!$C$39) -> 32.5 | K8: C$1.17/bbl per US$1 WTI after royalties, at 1.38 USD/CAD
A9: Cash flow
A10: Adjusted EBITDA | B10: C$M | G10: =G6*365*G8/1000 -> 645.32 | H10: =H6*365*H8/1000 -> 584.9636 | I10: =I6*365*I8/1000 -> 593.125 | J10: =J6*365*J8/1000 -> 640.575
A11: Interest | B11: C$M | G11: =Inputs!G14 -> 45 | H11: =Inputs!H14 -> 38 | I11: =Inputs!I14 -> 32 | J11: =Inputs!J14 -> 26
A12: Adjusted funds flow | B12: C$M | C12: =Inputs!C11 -> 143.5 | G12: =G10-G11 -> 600.32 | H12: =H10-H11 -> 546.9636 | I12: =I10-I11 -> 561.125 | J12: =J10-J11 -> 614.575 | K12: No cash taxes expected before 2030
A13: Basic shares | B13: M | F13: =Inputs!F16 -> 240.4 | G13: =Inputs!G16 -> 240.4 | H13: =Inputs!H16 -> 240.4 | I13: =Inputs!I16 -> 240.4 | J13: =Inputs!J16 -> 240.4
A14: Adjusted funds flow per share | B14: C$ | G14: =G12/G13 -> 2.4971714 | H14: =H12/H13 -> 2.275223 | I14: =I12/I13 -> 2.3341306 | J14: =J12/J13 -> 2.5564684
A15: Capital expenditures | B15: C$M | C15: =Inputs!C12 -> 111.8 | G15: =Inputs!G15 -> 330 | H15: =Inputs!H15 -> 300 | I15: =Inputs!I15 -> 300 | J15: =Inputs!J15 -> 300
A16: Free cash flow | B16: C$M | C16: =Inputs!C13 -> 31.7 | G16: =G12-G15 -> 270.32 | H16: =H12-H15 -> 246.9636 | I16: =I12-I15 -> 261.125 | J16: =J12-J15 -> 314.575
A17: Free cash flow to the firm | B17: C$M | G17: =G16+G11 -> 315.32 | H17: =H16+H11 -> 284.9636 | I17: =I16+I11 -> 293.125 | J17: =J16+J11 -> 340.575
A18: Balance sheet
A19: Net debt, period end | B19: C$M | F19: =Inputs!F17 -> 530 | G19: =F19-G16 -> 259.68 | H19: =G19-H16 -> 12.7164 | I19: =H19-I16 -> -248.4086 | J19: =I19-J16 -> -562.9836
A20: Opening net debt / EBITDA | B20: x | G20: =F19/G10 -> 0.82129796 | H20: =G19/H10 -> 0.44392506 | I20: =H19/I10 -> 0.021439663 | J20: =I19/J10 -> -0.38779003

Sheet Valuation
A1: Greenfire Resources Ltd. — Valuation and price target
A2: Target methods first; CFA Level II cross-checks (DCF, reverse DCF, residual income, justified P/E) follow.
A4: Market data
A5: Share price (USD) | B5: =Inputs!$C$21 -> 7 | C5: NYSE close Oct 26, 2026 (StockScan)
A6: Share price in model currency (CAD) | B6: =Inputs!$C$21*Inputs!$C$22 -> 9.814 | C6: Converted when the listing currency differs from the reporting currency
A7: Basic shares outstanding (M) | B7: =Inputs!$C$23 -> 240.4
A8: Market capitalization (M) | B8: =Valuation!$B$6*Valuation!$B$7 -> 2359.2856
A9: Net debt (cash) at last balance sheet (M) | B9: =Inputs!$C$24 -> 570 | C9: Negative = net cash
A10: Enterprise value (M) | B10: =Valuation!$B$8+Valuation!$B$9 -> 2929.2856 | C10: Market cap + net debt
A12: Required return on equity (CAPM) and WACC — CFA L2 Equity: Return Concepts; Corporate Issuers: Cost of Capital
A13: Risk-free rate (US 10-yr) | B13: =Inputs!$C$43 -> 0.0497 | C13: House deck
A14: Equity beta | B14: =Inputs!$C$25 -> 1.3 | C14: Northwall assumption pending sourcing
A15: Equity risk premium | B15: =Inputs!$C$44 -> 0.05 | C15: House deck
A16: Cost of equity: rf + beta x ERP | B16: =Valuation!$B$13+Valuation!$B$14*Valuation!$B$15 -> 0.1147 | C16: CAPM
A17: Pre-tax cost of debt | B17: =Inputs!$C$26 -> 0.08 | C17: Northwall assumption: credit facility pricing
A18: Marginal tax rate | B18: =Inputs!$C$27 -> 0.23
A19: Debt weight: D / (D + E), market values | B19: =Inputs!$C$28/(Inputs!$C$28+Valuation!$B$8) -> 0.19458669 | C19: Gross debt at market cap
A20: WACC | B20: =Valuation!$B$16*(1-Valuation!$B$19)+Valuation!$B$17*(1-Valuation!$B$18)*Valuation!$B$19 -> 0.10436745 | C20: ke x E/V + kd x (1 - t) x D/V
A22: Target method 1: P/NAV (2P reserves) — method 2: EV/EBITDA
A23: Greenfire 2P after-tax PV10, YE2025 (C$M) | B23: =Inputs!$C$40 -> 1990 | C23: YE2025 reserves release
A24: Connacher 2P value (C$M) | B24: =Inputs!$C$41 -> 2000 | C24: Northwall estimate: 2P NAV10 before tax C$2,124M (acquisition release); no cash tax before 2030
A25: Net debt, Dec 31, 2026E (C$M) | B25: =Model!$F$19 -> 530
A26: NAV per share (C$) | B26: =(Valuation!$B$23+Valuation!$B$24-Valuation!$B$25)/Valuation!$B$7 -> 14.392679
A27: Target P/NAV multiple | B27: =Inputs!$C$30 -> 0.85 | C27: Northwall: discount for a 72% controlling shareholder and thin float
A28: Method 1 value per share (C$) | B28: =Valuation!$B$27*Valuation!$B$26 -> 12.233777
A29: Adjusted EBITDA, 2027E (C$M) | B29: =Model!$G$10 -> 645.32
A30: Target EV/EBITDA multiple, 2027E | B30: =Inputs!$C$31 -> 5 | C30: Northwall: in line with Strathcona at ~5.0x annualized EV/CF
A31: Method 2 value per share (C$) | B31: =(Valuation!$B$30*Valuation!$B$29-Valuation!$B$25)/Valuation!$B$7 -> 11.217138
A32: Current EV per flowing barrel (C$) | B32: =Valuation!$B$10*1000000/Inputs!$C$42 -> 86155.459 | C32: EV / current production
A33: Price target and rating
A34: Weight on method 1 | B34: =Inputs!$C$29 -> 0.5
A35: Weight on method 2 | B35: =1-Inputs!$C$29 -> 0.5
A36: Blended value per share (CAD) | B36: =Valuation!$B$34*Valuation!$B$28+Valuation!$B$35*Valuation!$B$31 -> 11.725458
A37: Blended value per share (USD) | B37: =Valuation!$B$36/Inputs!$C$22 -> 8.3633792 | C37: Converted to listing currency
A38: 12-month price target (USD), rounded | B38: =MROUND(Valuation!$B$37,Inputs!$C$33) -> 8.25 | C38: Rounded to the house increment
A39: Next-12-month dividend per share (listing currency) | B39: =Inputs!$C$32 -> 0 | C39: No dividend
A40: Implied price return | B40: =Valuation!$B$38/Valuation!$B$5-1 -> 0.17857143
A41: Dividend yield | B41: =Valuation!$B$39/Valuation!$B$5 -> 0
A42: Implied all-in return | B42: =Valuation!$B$40+Valuation!$B$41 -> 0.17857143 | C42: Rating bands: Buy > 15%, Hold 0–15%, Sell < 0%
A43: Rating | B43: =IF(Valuation!$B$42>Inputs!$C$34,"Buy",IF(Valuation!$B$42>=0,"Hold","Sell")) -> Buy
...

Sheet Sensitivity
A1: Greenfire Resources Ltd. — Sensitivity
A2: Every cell is a live formula on the model; nothing is pasted.
A4: Price target (USD, before rounding) vs. the two valuation multiples
A5: P/NAV down, EV/EBITDA 2027E across | B5: 4 | C5: 4.5 | D5: 5 | E5: 5.5 | F5: 6
A6: 0.7 | B6: =(Inputs!$C$29*$A6*Valuation!$B$26+(1-Inputs!$C$29)*(B$5*Valuation!$B$29-Valuation!$B$25)/Valuation!$B$7)/Inputs!$C$22 -> 6.6361105 | C6: =(Inputs!$C$29*$A6*Valuation!$B$26+(1-Inputs!$C$29)*(C$5*Valuation!$B$29-Valuation!$B$25)/Valuation!$B$7)/Inputs!$C$22 -> 7.1147766 | D6: =(Inputs!$C$29*$A6*Valuation!$B$26+(1-Inputs!$C$29)*(D$5*Valuation!$B$29-Valuation!$B$25)/Valuation!$B$7)/Inputs!$C$22 -> 7.5934427 | E6: =(Inputs!$C$29*$A6*Valuation!$B$26+(1-Inputs!$C$29)*(E$5*Valuation!$B$29-Valuation!$B$25)/Valuation!$B$7)/Inputs!$C$22 -> 8.0721088 | F6: =(Inputs!$C$29*$A6*Valuation!$B$26+(1-Inputs!$C$29)*(F$5*Valuation!$B$29-Valuation!$B$25)/Valuation!$B$7)/Inputs!$C$22 -> 8.5507749
A7: 0.775 | B7: =(Inputs!$C$29*$A7*Valuation!$B$26+(1-Inputs!$C$29)*(B$5*Valuation!$B$29-Valuation!$B$25)/Valuation!$B$7)/Inputs!$C$22 -> 7.0210788 | C7: =(Inputs!$C$29*$A7*Valuation!$B$26+(1-Inputs!$C$29)*(C$5*Valuation!$B$29-Valuation!$B$25)/Valuation!$B$7)/Inputs!$C$22 -> 7.4997448 | D7: =(Inputs!$C$29*$A7*Valuation!$B$26+(1-Inputs!$C$29)*(D$5*Valuation!$B$29-Valuation!$B$25)/Valuation!$B$7)/Inputs!$C$22 -> 7.9784109 | E7: =(Inputs!$C$29*$A7*Valuation!$B$26+(1-Inputs!$C$29)*(E$5*Valuation!$B$29-Valuation!$B$25)/Valuation!$B$7)/Inputs!$C$22 -> 8.457077 | F7: =(Inputs!$C$29*$A7*Valuation!$B$26+(1-Inputs!$C$29)*(F$5*Valuation!$B$29-Valuation!$B$25)/Valuation!$B$7)/Inputs!$C$22 -> 8.9357431
A8: 0.85 | B8: =(Inputs!$C$29*$A8*Valuation!$B$26+(1-Inputs!$C$29)*(B$5*Valuation!$B$29-Valuation!$B$25)/Valuation!$B$7)/Inputs!$C$22 -> 7.406047 | C8: =(Inputs!$C$29*$A8*Valuation!$B$26+(1-Inputs!$C$29)*(C$5*Valuation!$B$29-Valuation!$B$25)/Valuation!$B$7)/Inputs!$C$22 -> 7.8847131 | D8: =(Inputs!$C$29*$A8*Valuation!$B$26+(1-Inputs!$C$29)*(D$5*Valuation!$B$29-Valuation!$B$25)/Valuation!$B$7)/Inputs!$C$22 -> 8.3633792 | E8: =(Inputs!$C$29*$A8*Valuation!$B$26+(1-Inputs!$C$29)*(E$5*Valuation!$B$29-Valuation!$B$25)/Valuation!$B$7)/Inputs!$C$22 -> 8.8420452 | F8: =(Inputs!$C$29*$A8*Valuation!$B$26+(1-Inputs!$C$29)*(F$5*Valuation!$B$29-Valuation!$B$25)/Valuation!$B$7)/Inputs!$C$22 -> 9.3207113
A9: 0.925 | B9: =(Inputs!$C$29*$A9*Valuation!$B$26+(1-Inputs!$C$29)*(B$5*Valuation!$B$29-Valuation!$B$25)/Valuation!$B$7)/Inputs!$C$22 -> 7.7910152 | C9: =(Inputs!$C$29*$A9*Valuation!$B$26+(1-Inputs!$C$29)*(C$5*Valuation!$B$29-Valuation!$B$25)/Valuation!$B$7)/Inputs!$C$22 -> 8.2696813 | D9: =(Inputs!$C$29*$A9*Valuation!$B$26+(1-Inputs!$C$29)*(D$5*Valuation!$B$29-Valuation!$B$25)/Valuation!$B$7)/Inputs!$C$22 -> 8.7483474 | E9: =(Inputs!$C$29*$A9*Valuation!$B$26+(1-Inputs!$C$29)*(E$5*Valuation!$B$29-Valuation!$B$25)/Valuation!$B$7)/Inputs!$C$22 -> 9.2270135 | F9: =(Inputs!$C$29*$A9*Valuation!$B$26+(1-Inputs!$C$29)*(F$5*Valuation!$B$29-Valuation!$B$25)/Valuation!$B$7)/Inputs!$C$22 -> 9.7056795
A10: 1 | B10: =(Inputs!$C$29*$A10*Valuation!$B$26+(1-Inputs!$C$29)*(B$5*Valuation!$B$29-Valuation!$B$25)/Valuation!$B$7)/Inputs!$C$22 -> 8.1759834 | C10: =(Inputs!$C$29*$A10*Valuation!$B$26+(1-Inputs!$C$29)*(C$5*Valuation!$B$29-Valuation!$B$25)/Valuation!$B$7)/Inputs!$C$22 -> 8.6546495 | D10: =(Inputs!$C$29*$A10*Valuation!$B$26+(1-Inputs!$C$29)*(D$5*Valuation!$B$29-Valuation!$B$25)/Valuation!$B$7)/Inputs!$C$22 -> 9.1333156 | E10: =(Inputs!$C$29*$A10*Valuation!$B$26+(1-Inputs!$C$29)*(E$5*Valuation!$B$29-Valuation!$B$25)/Valuation!$B$7)/Inputs!$C$22 -> 9.6119817 | F10: =(Inputs!$C$29*$A10*Valuation!$B$26+(1-Inputs!$C$29)*(F$5*Valuation!$B$29-Valuation!$B$25)/Valuation!$B$7)/Inputs!$C$22 -> 10.090648
A13: DCF value per share vs. WACC (down) and terminal growth (across)
B14: 0 | C14: 0.01 | D14: 0.02 | E14: 0.03
A15: 0.06 | B15: =(Valuation!B48/(1+$A15)^1+Valuation!C48/(1+$A15)^2+Valuation!D48/(1+$A15)^3+Valuation!E48/(1+$A15)^4+Valuation!E48*(1+B$14)/($A15-B$14)/(1+$A15)^4-Valuation!$B$57+Valuation!$B$58)/Valuation!$B$7 -> 20.936317 | C15: =(Valuation!B48/(1+$A15)^1+Valuation!C48/(1+$A15)^2+Valuation!D48/(1+$A15)^3+Valuation!E48/(1+$A15)^4+Valuation!E48*(1+C$14)/($A15-C$14)/(1+$A15)^4-Valuation!$B$57+Valuation!$B$58)/Valuation!$B$7 -> 24.901283 | D15: =(Valuation!B48/(1+$A15)^1+Valuation!C48/(1+$A15)^2+Valuation!D48/(1+$A15)^3+Valuation!E48/(1+$A15)^4+Valuation!E48*(1+D$14)/($A15-D$14)/(1+$A15)^4-Valuation!$B$57+Valuation!$B$58)/Valuation!$B$7 -> 30.848732 | E15: =(Valuation!B48/(1+$A15)^1+Valuation!C48/(1+$A15)^2+Valuation!D48/(1+$A15)^3+Valuation!E48/(1+$A15)^4+Valuation!E48*(1+E$14)/($A15-E$14)/(1+$A15)^4-Valuation!$B$57+Valuation!$B$58)/Valuation!$B$7 -> 40.761146
A16: 0.07 | B16: =(Valuation!B48/(1+$A16)^1+Valuation!C48/(1+$A16)^2+Valuation!D48/(1+$A16)^3+Valuation!E48/(1+$A16)^4+Valuation!E48*(1+B$14)/($A16-B$14)/(1+$A16)^4-Valuation!$B$57+Valuation!$B$58)/Valuation!$B$7 -> 17.572578 | C16: =(Valuation!B48/(1+$A16)^1+Valuation!C48/(1+$A16)^2+Valuation!D48/(1+$A16)^3+Valuation!E48/(1+$A16)^4+Valuation!E48*(1+C$14)/($A16-C$14)/(1+$A16)^4-Valuation!$B$57+Valuation!$B$58)/Valuation!$B$7 -> 20.326031 | D16: =(Valuation!B48/(1+$A16)^1+Valuation!C48/(1+$A16)^2+Valuation!D48/(1+$A16)^3+Valuation!E48/(1+$A16)^4+Valuation!E48*(1+D$14)/($A16-D$14)/(1+$A16)^4-Valuation!$B$57+Valuation!$B$58)/Valuation!$B$7 -> 24.180866 | E16: =(Valuation!B48/(1+$A16)^1+Valuation!C48/(1+$A16)^2+Valuation!D48/(1+$A16)^3+Valuation!E48/(1+$A16)^4+Valuation!E48*(1+E$14)/($A16-E$14)/(1+$A16)^4-Valuation!$B$57+Valuation!$B$58)/Valuation!$B$7 -> 29.963117
A17: 0.08 | B17: =(Valuation!B48/(1+$A17)^1+Valuation!C48/(1+$A17)^2+Valuation!D48/(1+$A17)^3+Valuation!E48/(1+$A17)^4+Valuation!E48*(1+B$14)/($A17-B$14)/(1+$A17)^4-Valuation!$B$57+Valuation!$B$58)/Valuation!$B$7 -> 15.051822 | C17: =(Valuation!B48/(1+$A17)^1+Valuation!C48/(1+$A17)^2+Valuation!D48/(1+$A17)^3+Valuation!E48/(1+$A17)^4+Valuation!E48*(1+C$14)/($A17-C$14)/(1+$A17)^4-Valuation!$B$57+Valuation!$B$58)/Valuation!$B$7 -> 17.060078 | D17: =(Valuation!B48/(1+$A17)^1+Valuation!C48/(1+$A17)^2+Valuation!D48/(1+$A17)^3+Valuation!E48/(1+$A17)^4+Valuation!E48*(1+D$14)/($A17-D$14)/(1+$A17)^4-Valuation!$B$57+Valuation!$B$58)/Valuation!$B$7 -> 19.737752 | E17: =(Valuation!B48/(1+$A17)^1+Valuation!C48/(1+$A17)^2+Valuation!D48/(1+$A17)^3+Valuation!E48/(1+$A17)^4+Valuation!E48*(1+E$14)/($A17-E$14)/(1+$A17)^4-Valuation!$B$57+Valuation!$B$58)/Valuation!$B$7 -> 23.486496
A18: 0.09 | B18: =(Valuation!B48/(1+$A18)^1+Valuation!C48/(1+$A18)^2+Valuation!D48/(1+$A18)^3+Valuation!E48/(1+$A18)^4+Valuation!E48*(1+B$14)/($A18-B$14)/(1+$A18)^4-Valuation!$B$57+Valuation!$B$58)/Valuation!$B$7 -> 13.092969 | C18: =(Valuation!B48/(1+$A18)^1+Valuation!C48/(1+$A18)^2+Valuation!D48/(1+$A18)^3+Valuation!E48/(1+$A18)^4+Valuation!E48*(1+C$14)/($A18-C$14)/(1+$A18)^4-Valuation!$B$57+Valuation!$B$58)/Valuation!$B$7 -> 14.612349 | D18: =(Valuation!B48/(1+$A18)^1+Valuation!C48/(1+$A18)^2+Valuation!D48/(1+$A18)^3+Valuation!E48/(1+$A18)^4+Valuation!E48*(1+D$14)/($A18-D$14)/(1+$A18)^4-Valuation!$B$57+Valuation!$B$58)/Valuation!$B$7 -> 16.565837 | E18: =(Valuation!B48/(1+$A18)^1+Valuation!C48/(1+$A18)^2+Valuation!D48/(1+$A18)^3+Valuation!E48/(1+$A18)^4+Valuation!E48*(1+E$14)/($A18-E$14)/(1+$A18)^4-Valuation!$B$57+Valuation!$B$58)/Valuation!$B$7 -> 19.170488
A19: 0.1 | B19: =(Valuation!B48/(1+$A19)^1+Valuation!C48/(1+$A19)^2+Valuation!D48/(1+$A19)^3+Valuation!E48/(1+$A19)^4+Valuation!E48*(1+B$14)/($A19-B$14)/(1+$A19)^4-Valuation!$B$57+Valuation!$B$58)/Valuation!$B$7 -> 11.527376 | C19: =(Valuation!B48/(1+$A19)^1+Valuation!C48/(1+$A19)^2+Valuation!D48/(1+$A19)^3+Valuation!E48/(1+$A19)^4+Valuation!E48*(1+C$14)/($A19-C$14)/(1+$A19)^4-Valuation!$B$57+Valuation!$B$58)/Valuation!$B$7 -> 12.71003 | D19: =(Valuation!B48/(1+$A19)^1+Valuation!C48/(1+$A19)^2+Valuation!D48/(1+$A19)^3+Valuation!E48/(1+$A19)^4+Valuation!E48*(1+D$14)/($A19-D$14)/(1+$A19)^4-Valuation!$B$57+Valuation!$B$58)/Valuation!$B$7 -> 14.188348 | E19: =(Valuation!B48/(1+$A19)^1+Valuation!C48/(1+$A19)^2+Valuation!D48/(1+$A19)^3+Valuation!E48/(1+$A19)^4+Valuation!E48*(1+E$14)/($A19-E$14)/(1+$A19)^4-Valuation!$B$57+Valuation!$B$58)/Valuation!$B$7 -> 16.089042

Sheet Ratios
A1: Greenfire Resources Ltd. — Financial analysis ratios
A2: CFA L2 Financial Statement Analysis: DuPont, cash conversion, leverage and payout. Formulas on the Model sheet.
A4: Ratio | B4: Unit | C4: 2025A | D4: H1-26A | E4: H2-26E | F4: 2026E | G4: 2027E | H4: 2028E | I4: 2029E | J4: 2030E | K4: Reading
A5: Opening net debt / EBITDA | G5: =IFERROR(Model!F19/Model!G10,"") -> 0.82129796 | H5: =IFERROR(Model!G19/Model!H10,"") -> 0.44392506 | I5: =IFERROR(Model!H19/Model!I10,"") -> 0.021439663 | J5: =IFERROR(Model!I19/Model!J10,"") -> -0.38779003
A6: Reinvestment rate (capital / adjusted funds flow) | C6: =IFERROR(Model!C15/Model!C12,"") -> 0.77909408 | G6: =IFERROR(Model!G15/Model!G12,"") -> 0.54970682 | H6: =IFERROR(Model!H15/Model!H12,"") -> 0.54848257 | I6: =IFERROR(Model!I15/Model!I12,"") -> 0.53464023 | J6: =IFERROR(Model!J15/Model!J12,"") -> 0.48814221
A7: Free cash flow conversion (FCF / AFF) | C7: =IFERROR(Model!C16/Model!C12,"") -> 0.22090592 | G7: =IFERROR(Model!G16/Model!G12,"") -> 0.45029318 | H7: =IFERROR(Model!H16/Model!H12,"") -> 0.45151743 | I7: =IFERROR(Model!I16/Model!I12,"") -> 0.46535977 | J7: =IFERROR(Model!J16/Model!J12,"") -> 0.51185779
A8: EBITDA margin per barrel at deck (C$/bbl) | G8: =IFERROR(Model!G8,"") -> 44.2 | H8: =IFERROR(Model!H8,"") -> 34.84 | I8: =IFERROR(Model!I8,"") -> 32.5 | J8: =IFERROR(Model!J8,"") -> 32.5

Sheet Comps
A1: Greenfire Resources Ltd. — Peer comparison
A2: Oil sands and heavy oil peers, EV per flowing barrel. GFR at US$7.00 x 1.402; SCR Oct 15; ATH Oct 16, 2026.
A4: Company | B4: Ticker | C4: Price (C$) | D4: Mkt cap (C$B) | E4: EV (C$B) | F4: Production (bbl/d) | G4: EV/flowing bbl (C$k)
A5: Greenfire | B5: GFR | C5: 9.81 | D5: 2.4 | E5: 2.9 | F5: 34000 | G5: 86
A6: Strathcona | B6: SCR | C6: 41.73 | D6: 8.9 | E6: 10.9 | F6: 117022 | G6: 93
A7: Athabasca Oil | B7: ATH | C7: 12.15 | D7: 5.9 | E7: 5.8 | F7: 40000 | G7: 146
A9: Source: Company filings; Northwall calculations

Sheet Checks
A1: Greenfire Resources Ltd. — Model integrity checks
A2: Every check should read TRUE before anything is published.
A4: Check | B4: Model | C4: Expected | D4: Pass
A5: Price target equals the published target | B5: =Valuation!$B$38 -> 8.25 | C5: 8.25 | D5: =ABS(B5-C5)<=MAX(0.01,ABS(C5)*0.005) -> TRUE
A6: Rating equals the published rating | B6: =Valuation!$B$43 -> Buy | C6: Buy | D6: =B6=C6 -> TRUE
A7: 2027E adjusted EBITDA equals the published estimate | B7: =Model!$G$10 -> 645.32 | C7: 645.32 | D7: =ABS(B7-C7)<=MAX(0.01,ABS(C7)*0.005) -> TRUE
A8: 2027E AFF per share equals the published estimate | B8: =Model!$G$14 -> 2.4971714 | C8: 2.5 | D8: =ABS(B8-C8)<=MAX(0.01,ABS(C8)*0.005) -> TRUE
A9: Blended value (C$) equals the published C$ target | B9: =Valuation!$B$36 -> 11.725458 | C9: 11.73 | D9: =ABS(B9-C9)<=MAX(0.01,ABS(C9)*0.005) -> TRUE
A10: NAV per share equals the published NAVPS | B10: =Valuation!$B$26 -> 14.392679 | C10: 14.39 | D10: =ABS(B10-C10)<=MAX(0.01,ABS(C10)*0.005) -> TRUE
A12: All checks pass | D12: =AND(D5:D10) -> TRUE

Sheet Log
A1: Model change log
A2: Newest first. One row per change; never delete rows.
A4: Date | B4: Version | C4: Change | D4: Effect on target
A5: 2026-10-27 | B5: v2026Q2 | C5: Model built on house template from Q2-26 filings; ties to the published 2026-10-27 report | D5: Target US$8.25, Buy
